Workbook

Sheet README
A1: NIST CSF 2.0 Document Framework: Document Register and Traceability
A2: Purpose: one list of every controlled document, its classification, ownership, and mapping to NIST CSF 2.0, ISO/IEC 27001:2022, NIST SP 800-53 Rev. 5, and Thai law.
A3: Sheets: Summary (counts by formula), Document Register (one row per document), Implementation Roadmap (recommended build order), Prerequisite Activities (meetings and workshops with agendas), Process Flows (operating chains), CSF Traceability (one row per CSF 2.0 subcategory), Hierarchy (parent to child links), Verify List (items to confirm with current Thai regulations).
A4: ISO 27002 Theme: the theme of the first ISO/IEC 27001:2022 Annex A control mapped to the document (A.5 Organizational, A.6 People, A.7 Physical, A.8 Technological); documents mapped only to management system clauses count as Organizational. NIST does not publish a theme grouping.
A5: Build Order, Wave, Track: practitioner guidance for an organization starting from scratch. Track A builds governance in overlapping waves (W0 Mandate to W5 Optimize). Track B runs threat-driven quick wins in parallel from day one.
A6: Capability: IT-ready = in-house IT can produce it from the template; Specialist-guided = IT drafts, a cybersecurity specialist facilitates or reviews; Specialist-required = needs a security FTE, consultant, or managed service.
A7: Level: Required = mandated by law or a certifiable standard when the Trigger applies; Expected = auditors, regulators, or customers expect it; Optional = adds value at higher maturity.
A8: Trigger: All, PDPA, ISO 27001 (certification), CII (Critical Information Infrastructure), CCA (service provider under the Computer Crime Act B.E. 2550 s.26).
A9: Package (cumulative): Essential = the smallest self-contained starter set every organization should have; Core = the rest of the full baseline, built on Essential (every Core document sits under an Essential document); Extended = higher maturity or specific contexts. Level answers whether a document is mandated; Package answers how much to adopt for the organization's size. A Required document applies whenever its trigger applies, whatever its package.
A10: Edit cells in the Document Register to track your own status; the Summary sheet recalculates.
A11: References as of October 2026. Items marked [VERIFY] must be confirmed against current Thai regulations before use. This pack is a sample and is not legal advice.

Sheet Summary
A1: Summary (formulas reference the Document Register sheet)
A3: By Function | B3: Count
A4: Govern | B4: =COUNTIF('Document Register'!$D$2:$D$143,"Govern*") -> 47
A5: Identify | B5: =COUNTIF('Document Register'!$D$2:$D$143,"Identify*") -> 23
A6: Protect | B6: =COUNTIF('Document Register'!$D$2:$D$143,"Protect*") -> 41
A7: Detect | B7: =COUNTIF('Document Register'!$D$2:$D$143,"Detect*") -> 8
A8: Respond | B8: =COUNTIF('Document Register'!$D$2:$D$143,"Respond*") -> 14
A9: Recover | B9: =COUNTIF('Document Register'!$D$2:$D$143,"Recover*") -> 9
A10: Total | B10: =SUM(B4:B9) -> 142
A12: By Tier | B12: Count
A13: T0 | B13: =COUNTIF('Document Register'!$F$2:$F$143,"T0*") -> 4
A14: T1 | B14: =COUNTIF('Document Register'!$F$2:$F$143,"T1*") -> 10
A15: T2 | B15: =COUNTIF('Document Register'!$F$2:$F$143,"T2*") -> 24
A16: T3 | B16: =COUNTIF('Document Register'!$F$2:$F$143,"T3*") -> 44
A17: T4 | B17: =COUNTIF('Document Register'!$F$2:$F$143,"T4*") -> 60
A18: Total | B18: =SUM(B13:B17) -> 142
A20: By ISO/IEC 27002 Theme | B20: Count
A21: Organizational | B21: =COUNTIF('Document Register'!$H$2:$H$143,"Organizational*") -> 94
A22: People | B22: =COUNTIF('Document Register'!$H$2:$H$143,"People*") -> 8
A23: Physical | B23: =COUNTIF('Document Register'!$H$2:$H$143,"Physical*") -> 4
A24: Technological | B24: =COUNTIF('Document Register'!$H$2:$H$143,"Technological*") -> 36
A25: Total | B25: =SUM(B21:B24) -> 142
A27: By Wave (recommended build order) | B27: Count
A28: W0 Mandate and Mobilize | B28: =COUNTIF('Document Register'!$X$2:$X$143,"W0 Mandate and Mobilize*") -> 15
A29: W1 Understand | B29: =COUNTIF('Document Register'!$X$2:$X$143,"W1 Understand*") -> 22
A30: W2 Direct | B30: =COUNTIF('Document Register'!$X$2:$X$143,"W2 Direct*") -> 25
A31: W3 Standardize | B31: =COUNTIF('Document Register'!$X$2:$X$143,"W3 Standardize*") -> 57
A32: W4 Operate and Prove | B32: =COUNTIF('Document Register'!$X$2:$X$143,"W4 Operate and Prove*") -> 14
A33: W5 Optimize | B33: =COUNTIF('Document Register'!$X$2:$X$143,"W5 Optimize*") -> 9
A34: Total | B34: =SUM(B28:B33) -> 142
A36: By Capability | B36: Count
A37: IT-ready | B37: =COUNTIF('Document Register'!$Z$2:$Z$143,"IT-ready*") -> 54
A38: Specialist-guided | B38: =COUNTIF('Document Register'!$Z$2:$Z$143,"Specialist-guided*") -> 54
A39: Specialist-required | B39: =COUNTIF('Document Register'!$Z$2:$Z$143,"Specialist-required*") -> 34
A40: Total | B40: =SUM(B37:B39) -> 142
A42: By Package | B42: Count
A43: Essential | B43: =COUNTIF('Document Register'!$I$2:$I$143,"Essential*") -> 59
A44: Core | B44: =COUNTIF('Document Register'!$I$2:$I$143,"Core*") -> 67
A45: Extended | B45: =COUNTIF('Document Register'!$I$2:$I$143,"Extended*") -> 16
A46: Total | B46: =SUM(B43:B45) -> 142
...

Sheet Document Register
A1: Document ID | B1: Title (EN) | C1: Title (TH) | D1: Function | E1: Category | F1: Tier | G1: Type | H1: ISO 27002 Theme | I1: Package | J1: Level | K1: Trigger | L1: Basis | M1: Level for CMC | N1: CSF 2.0 Subcategories | O1: ISO/IEC 27001:2022 | P1: NIST SP 800-53 Rev. 5 | Q1: Owner (role) | R1: Approver (role) | S1: Review Cycle | T1: Parent Documents | U1: Child Documents | V1: Tags | W1: Build Order | X1: Wave | Y1: Track | Z1: Capability | AA1: Sourcing Options | AB1: Prerequisite Activities | AC1: Depends On | AD1: File (Template EN) | AE1: Status (your organization)
A2: GV-CHR-001 | B2: Cybersecurity Governance Charter | C2: กฎบัตรการกำกับดูแลความมั่นคงปลอดภัยไซเบอร์ | D2: Govern (GV) | E2: Organizational Context (GV.OC) | F2: T0 | G2: Charter | H2: Organizational | I2: Essential | J2: Expected | K2: All | L2: ISO/IEC 27001:2022 Clause 5.1 and 5.3; CSA s.44 (CII) | M2: Expected | N2: GV.OC-01, GV.RR-01, GV.OV-01 | O2: 5.1, 5.3, A.5.4 | P2: PM-1, PM-2, PM-29 | Q2: Chief Information Security Officer (CISO) or Security Manager | R2: Board of Directors | S2: Annual | U2: GV-STR-001, GV-RPT-001, GV-STM-001, GV-CHR-002, GV-REG-003, GV-POL-001, GV-PRC-007, RC-POL-001 | V2: Governance | W2: 1 | X2: W0 Mandate and Mobilize | Y2: Track A | Z2: Specialist-guided | AA2: In-house IT / Cybersecurity consultant (project) | AB2: ACT-01 Executive Kickoff and Mandate Meeting; ACT-02 Governance Structure and RACI Workshop | AD2: 02_Template_EN/01_GV_Govern/GV.OC_Organizational-Context/GV-CHR-001_Cybersecurity-Governance-Charter.docx | AE2: Not started
A3: GV-STR-001 | B3: Cybersecurity Strategy and Roadmap | C3: ยุทธศาสตร์และแผนงานด้านความมั่นคงปลอดภัยไซเบอร์ | D3: Govern (GV) | E3: Organizational Context (GV.OC) | F3: T0 | G3: Strategy | H3: Organizational | I3: Core | J3: Required | K3: ISO 27001 | L3: ISO/IEC 27001:2022 Clause 6.2 (documented information on information security objectives; the roadmap section is common practice) | M3: Expected | N3: GV.OC-01, GV.RM-01, GV.OV-01 | O3: 6.2 | P3: PM-1, PM-9 | Q3: Chief Information Security Officer (CISO) or Security Manager | R3: Board of Directors | S3: Annual | T3: GV-CHR-001 | U3: GV-PLN-001, GV-REG-008 | V3: Governance | W3: 38 | X3: W2 Direct | Y3: Track A | Z3: Specialist-guided | AA3: Cybersecurity consultant (project) / Security FTE | AB3: ACT-11 Current State Assessment and CSF Profile Gap Analysis; ACT-12 Strategy, Roadmap, and Budget Planning Session | AC3: ID-RPT-003, GV-RPT-001 | AD3: 02_Template_EN/01_GV_Govern/GV.OC_Organizational-Context/GV-STR-001_Cybersecurity-Strategy-and-Roadmap.docx | AE3: Not started
A4: GV-RPT-001 | B4: Organizational Context and ISMS Scope Statement | C4: เอกสารบริบทองค์กรและขอบเขตระบบบริหารจัดการความมั่นคงปลอดภัยสารสนเทศ | D4: Govern (GV) | E4: Organizational Context (GV.OC) | F4: T4 | G4: Report | H4: Organizational | I4: Core | J4: Required | K4: ISO 27001 | L4: ISO/IEC 27001:2022 Clause 4.3 (scope as documented information) | M4: Expected | N4: GV.OC-01, GV.OC-02, GV.OC-04, GV.OC-05 | O4: 4.1, 4.2, 4.3 | P4: PM-11, PM-8 | Q4: Chief Information Security Officer (CISO) or Security Manager | R4: Information Security Steering Committee (ISSC) | S4: Annual | T4: GV-CHR-001 | U4: GV-REG-001, GV-REG-002 | V4: Governance, Evidence | W4: 16 | X4: W1 Understand | Y4: Track A | Z4: Specialist-guided | AA4: Cybersecurity consultant (project) / Security FTE | AB4: ACT-04 Scope and Organizational Context Workshop | AC4: GV-CHR-001, GV-REG-001 | AD4: 02_Template_EN/01_GV_Govern/GV.OC_Organizational-Context/GV-RPT-001_Organizational-Context-and-ISMS-Scope-Statement.docx | AE4: Not started
A5: GV-REG-001 | B5: Legal, Regulatory, and Contractual Requirements Register | C5: ทะเบียนข้อกำหนดด้านกฎหมาย ระเบียบ และสัญญา | D5: Govern (GV) | E5: Organizational Context (GV.OC) | F5: T4 | G5: Register | H5: Organizational | I5: Essential | J5: Expected | K5: All | L5: ISO/IEC 27001:2022 Annex A 5.31; PDPA; CSA | M5: Expected | N5: GV.OC-03 | O5: A.5.31, A.5.32, A.5.34 | P5: PM-1, PT-1 | Q5: Legal Counsel | R5: Information Security Steering Committee (ISSC) | S5: Annual and on legal change | T5: GV-RPT-001 | U5: GV-REG-006 | V5: Governance, Evidence, Legal and Regulatory | W5: 4 | X5: W0 Mandate and Mobilize | Y5: Track A | Z5: Specialist-required | AA5: Legal counsel / Cybersecurity consultant (project) | AB5: ACT-03 Legal and Regulatory Applicability Review | AD5: 02_Template_EN/01_GV_Govern/GV.OC_Organizational-Context/GV-REG-001_Legal-Regulatory-and-Contractual-Requirements-Register.docx | AE5: Not started
A6: GV-REG-002 | B6: Stakeholder Requirements Register | C6: ทะเบียนความคาดหวังของผู้มีส่วนได้ส่วนเสีย | D6: Govern (GV) | E6: Organizational Context (GV.OC) | F6: T4 | G6: Register | H6: Organizational | I6: Extended | J6: Expected | K6: ISO 27001 | L6: ISO/IEC 27001:2022 Clause 4.2 (not mandated as documented information) | M6: Expected | N6: GV.OC-02 | O6: 4.2 | P6: PM-11 | Q6: Chief Information Security Officer (CISO) or Security Manager | R6: Information Security Steering Committee (ISSC) | S6: Annual | T6: GV-RPT-001 | V6: Governance, Evidence | W6: 17 | X6: W1 Understand | Y6: Track A | Z6: IT-ready | AA6: In-house IT | AB6: ACT-04 Scope and Organizational Context Workshop | AC6: GV-RPT-001 | AD6: 02_Template_EN/01_GV_Govern/GV.OC_Organizational-Context/GV-REG-002_Stakeholder-Requirements-Register.docx | AE6: Not started
A7: GV-STM-001 | B7: Risk Appetite and Tolerance Statement | C7: แถลงการณ์ระดับความเสี่ยงที่ยอมรับได้และค่าเบี่ยงเบนที่ยอมรับได้ | D7: Govern (GV) | E7: Risk Management Strategy (GV.RM) | F7: T0 | G7: Statement | H7: Organizational | I7: Essential | J7: Expected | K7: All | L7: NIST IR 8286; ISO/IEC 27001:2022 Clause 6.1.2(a) risk acceptance criteria | M7: Expected | N7: GV.RM-01, GV.RM-02, GV.RM-03 | O7: 6.1.2 | P7: PM-9, PM-28 | Q7: Chief Risk Officer (CRO) or Enterprise Risk Manager | R7: Board of Directors | S7: Annual | T7: GV-CHR-001 | U7: GV-POL-002 | V7: Governance | W7: 29 | X7: W1 Understand | Y7: Track A | Z7: Specialist-required | AA7: Cybersecurity consultant (project) | AB7: ACT-08 Risk Appetite Workshop | AC7: ID-RPT-002, GV-CHR-001 | AD7: 02_Template_EN/01_GV_Govern/GV.RM_Risk-Management-Strategy/GV-STM-001_Risk-Appetite-and-Tolerance-Statement.docx | AE7: Not started
A8: GV-POL-002 | B8: Cybersecurity Risk Management Policy | C8: นโยบายการบริหารความเสี่ยงด้านความมั่นคงปลอดภัยไซเบอร์ | D8: Govern (GV) | E8: Risk Management Strategy (GV.RM) | F8: T1 | G8: Policy | H8: Organizational | I8: Essential | J8: Expected | K8: All | L8: ISO/IEC 27001:2022 Clause 6.1; CSA s.44 (CII) | M8: Expected | N8: GV.RM-01, GV.RM-03, GV.RM-04, GV.RM-05, GV.RM-07, GV.SC-03 | O8: 6.1, 8.2, 8.3 | P8: RA-1, PM-9 | Q8: Chief Information Security Officer (CISO) or Security Manager | R8: Chief Executive Officer (CEO) | S8: Annual | T8: GV-POL-001, GV-STM-001 | U8: GV-PRC-001 | V8: Governance | W8: 30 | X8: W1 Understand | Y8: Track A | Z8: Specialist-guided | AA8: Cybersecurity consultant (project) / Security FTE | AB8: ACT-13 Policy Drafting and Stakeholder Review Cycle; ACT-14 Policy Approval and Communication | AC8: GV-POL-001, GV-STM-001 | AD8: 02_Template_EN/01_GV_Govern/GV.RM_Risk-Management-Strategy/GV-POL-002_Cybersecurity-Risk-Management-Policy.docx | AE8: Not started
A9: GV-PRC-001 | B9: Risk Assessment and Treatment Methodology | C9: ระเบียบวิธีการประเมินและจัดการความเสี่ยง | D9: Govern (GV) | E9: Risk Management Strategy (GV.RM) | F9: T3 | G9: Procedure | H9: Organizational | I9: Essential | J9: Required | K9: ISO 27001, CII | L9: ISO/IEC 27001:2022 Clause 6.1.2 and 6.1.3 (documented process); CSA s.54 | M9: Required | N9: GV.RM-06, ID.RA-03, ID.RA-04, ID.RA-05, ID.RA-06 | O9: 6.1.2, 6.1.3 | P9: RA-3, PM-9 | Q9: Chief Information Security Officer (CISO) or Security Manager | R9: Information Security Steering Committee (ISSC) | S9: Annual | T9: GV-POL-002 | U9: GV-FRM-001, GV-REG-005, ID-REG-005, ID-RPT-003, ID-PRC-004 | V9: Process, Legal and Regulatory | W9: 31 | X9: W1 Understand | Y9: Track A | Z9: Specialist-required | AA9: Cybersecurity consultant (project) / Security FTE | AB9: ACT-09 Risk Methodology Design and Calibration Session | AC9: GV-POL-002 | AD9: 02_Template_EN/01_GV_Govern/GV.RM_Risk-Management-Strategy/GV-PRC-001_Risk-Assessment-and-Treatment-Methodology.docx | AE9: Not started
A10: GV-FRM-001 | B10: Risk Acceptance Form | C10: แบบฟอร์มการยอมรับความเสี่ยง | D10: Govern (GV) | E10: Risk Management Strategy (GV.RM) | F10: T4 | G10: Form | H10: Organizational | I10: Core | J10: Expected | K10: ISO 27001 | L10: ISO/IEC 27001:2022 Clause 6.1.3(f) (risk owner approval of residual risk) | M10: Expected | N10: GV.RM-04, ID.RA-06 | O10: 6.1.3 | P10: RA-7, PM-9 | Q10: Chief Information Security Officer (CISO) or Security Manager | R10: Risk Owner | S10: Annual | T10: GV-PRC-001 | V10: Process, Evidence | W10: 41 | X10: W2 Direct | Y10: Track A | Z10: IT-ready | AA10: In-house IT | AC10: GV-PRC-001 | AD10: 02_Template_EN/01_GV_Govern/GV.RM_Risk-Management-Strategy/GV-FRM-001_Risk-Acceptance-Form.docx | AE10: Not started
A11: GV-CHR-002 | B11: Information Security Steering Committee Terms of Reference | C11: ขอบเขตอำนาจหน้าที่คณะกรรมการกำกับดูแลความมั่นคงปลอดภัยสารสนเทศ | D11: Govern (GV) | E11: Roles, Responsibilities, and Authorities (GV.RR) | F11: T0 | G11: Charter | H11: Organizational | I11: Essential | J11: Expected | K11: All | L11: ISO/IEC 27001:2022 Clause 5.1 and 5.3 | M11: Expected | N11: GV.RR-01, GV.OV-01, GV.OV-02 | O11: 5.1, 5.3 | P11: PM-2, PM-29 | Q11: Chief Information Security Officer (CISO) or Security Manager | R11: Chief Executive Officer (CEO) | S11: Annual | T11: GV-CHR-001 | U11: GV-PRC-006 | V11: Governance | W11: 2 | X11: W0 Mandate and Mobilize | Y11: Track A | Z11: IT-ready | AA11: In-house IT | AB11: ACT-02 Governance Structure and RACI Workshop | AC11: GV-CHR-001 | AD11: 02_Template_EN/01_GV_Govern/GV.RR_Roles-Responsibilities-and-Authorities/GV-CHR-002_Information-Security-Steering-Committee-Terms-of-Reference.docx | AE11: Not started
A12: GV-REG-003 | B12: Cybersecurity Roles, Responsibilities, and RACI Matrix | C12: ตารางบทบาท หน้าที่ และความรับผิดชอบด้านความมั่นคงปลอดภัย (RACI) | D12: Govern (GV) | E12: Roles, Responsibilities, and Authorities (GV.RR) | F12: T4 | G12: Register | H12: Organizational | I12: Essential | J12: Expected | K12: ISO 27001, CII | L12: ISO/IEC 27001:2022 Clause 5.3 and Annex A 5.2; CSA s.46 and s.52 (CII contact officers) | M12: Expected | N12: GV.RR-01, GV.RR-02 | O12: 5.3, A.5.2, A.5.3 | P12: PM-2, PS-9 | Q12: Chief Information Security Officer (CISO) or Security Manager | R12: Chief Information Officer (CIO) | S12: Annual | T12: GV-CHR-001 | U12: GV-TPL-001 | V12: People, Legal and Regulatory, Evidence | W12: 3 | X12: W0 Mandate and Mobilize | Y12: Track A | Z12: Specialist-guided | AA12: In-house IT / Cybersecurity consultant (project) | AB12: ACT-02 Governance Structure and RACI Workshop | AC12: GV-CHR-002 | AD12: 02_Template_EN/01_GV_Govern/GV.RR_Roles-Responsibilities-and-Authorities/GV-REG-003_Cybersecurity-Roles-Responsibilities-and-RACI-Matrix.docx | AE12: Not started
A13: GV-TPL-001 | B13: Cybersecurity Job Description Templates | C13: แม่แบบคำบรรยายลักษณะงานด้านความมั่นคงปลอดภัย | D13: Govern (GV) | E13: Roles, Responsibilities, and Authorities (GV.RR) | F13: T4 | G13: Template | H13: Organizational | I13: Extended | J13: Optional | K13: All | L13: Common practice; NICE Workforce Framework (NIST SP 800-181 Rev. 1) | M13: Optional | N13: GV.RR-02, GV.RR-04 | O13: A.5.2 | P13: PS-9 | Q13: Human Resources Director | R13: Chief Information Officer (CIO) | S13: Annual | T13: GV-REG-003 | V13: People, Evidence | W13: 134 | X13: W5 Optimize | Y13: Track A | Z13: IT-ready | AA13: Human Resources | AC13: GV-REG-003 | AD13: 02_Template_EN/01_GV_Govern/GV.RR_Roles-Responsibilities-and-Authorities/GV-TPL-001_Cybersecurity-Job-Description-Templates.docx | AE13: Not started
A14: GV-PLN-001 | B14: Cybersecurity Budget and Resource Plan | C14: แผนงบประมาณและทรัพยากรด้านความมั่นคงปลอดภัยไซเบอร์ | D14: Govern (GV) | E14: Roles, Responsibilities, and Authorities (GV.RR) | F14: T3 | G14: Plan | H14: Organizational | I14: Core | J14: Expected | K14: ISO 27001 | L14: ISO/IEC 27001:2022 Clause 7.1 (resources; not mandated as documented information) | M14: Expected | N14: GV.RR-03 | O14: 7.1 | P14: PM-3 | Q14: Chief Information Security Officer (CISO) or Security Manager | R14: Chief Financial Officer (CFO) | S14: Annual | T14: GV-STR-001 | V14: Governance | W14: 39 | X14: W2 Direct | Y14: Track A | Z14: Specialist-guided | AA14: Security FTE / In-house IT | AB14: ACT-12 Strategy, Roadmap, and Budget Planning Session | AC14: GV-STR-001 | AD14: 02_Template_EN/01_GV_Govern/GV.RR_Roles-Responsibilities-and-Authorities/GV-PLN-001_Cybersecurity-Budget-and-Resource-Plan.docx | AE14: Not started
A15: GV-STD-001 | B15: Human Resources Security Standard | C15: มาตรฐานความมั่นคงปลอดภัยด้านทรัพยากรบุคคล | D15: Govern (GV) | E15: Roles, Responsibilities, and Authorities (GV.RR) | F15: T2 | G15: Standard | H15: People | I15: Essential | J15: Expected | K15: All | L15: ISO/IEC 27001:2022 Annex A 6.1 to 6.5 | M15: Expected | N15: GV.RR-04, PR.AA-05 | O15: A.6.1, A.6.2, A.6.4, A.6.5 | P15: PS-2, PS-3, PS-4, PS-5, PS-7, PS-8 | Q15: Human Resources Director | R15: Information Security Steering Committee (ISSC) | S15: Annual | T15: GV-POL-001 | U15: GV-FRM-002, GV-FRM-003 | V15: People | W15: 51 | X15: W2 Direct | Y15: Track A | Z15: IT-ready | AA15: Human Resources | AB15: ACT-13 Policy Drafting and Stakeholder Review Cycle | AC15: GV-POL-001 | AD15: 02_Template_EN/01_GV_Govern/GV.RR_Roles-Responsibilities-and-Authorities/GV-STD-001_Human-Resources-Security-Standard.docx | AE15: Not started
A16: GV-FRM-002 | B16: Confidentiality and Non-Disclosure Agreement | C16: สัญญาการรักษาความลับ | D16: Govern (GV) | E16: Roles, Responsibilities, and Authorities (GV.RR) | F16: T4 | G16: Form | H16: People | I16: Essential | J16: Expected | K16: All | L16: ISO/IEC 27001:2022 Annex A 6.6 | M16: Expected | N16: GV.RR-04, GV.SC-05 | O16: A.6.6 | P16: PS-6 | Q16: Legal Counsel | R16: Legal Counsel | S16: Annual | T16: GV-STD-001 | V16: People, Evidence, Legal and Regulatory | W16: 52 | X16: W2 Direct | Y16: Track A | Z16: Specialist-guided | AA16: Legal counsel | AC16: GV-STD-001 | AD16: 02_Template_EN/01_GV_Govern/GV.RR_Roles-Responsibilities-and-Authorities/GV-FRM-002_Confidentiality-and-Non-Disclosure-Agreement.docx | AE16: Not started
A17: GV-FRM-003 | B17: Employee Offboarding Security Checklist | C17: แบบตรวจสอบด้านความมั่นคงปลอดภัยเมื่อพนักงานพ้นสภาพหรือย้ายงาน | D17: Govern (GV) | E17: Roles, Responsibilities, and Authorities (GV.RR) | F17: T4 | G17: Form | H17: People | I17: Essential | J17: Expected | K17: All | L17: ISO/IEC 27001:2022 Annex A 5.11 and 6.5 | M17: Expected | N17: GV.RR-04, PR.AA-05, ID.AM-08 | O17: A.5.11, A.6.5 | P17: PS-4, PS-5 | Q17: Human Resources Director | R17: Human Resources Director | S17: Annual | T17: GV-STD-001 | V17: People, Evidence | W17: 53 | X17: W2 Direct | Y17: Track A | Z17: IT-ready | AA17: Human Resources / In-house IT | AC17: GV-STD-001 | AD17: 02_Template_EN/01_GV_Govern/GV.RR_Roles-Responsibilities-and-Authorities/GV-FRM-003_Employee-Offboarding-Security-Checklist.docx | AE17: Not started
A18: GV-POL-001 | B18: Information Security Policy | C18: นโยบายความมั่นคงปลอดภัยสารสนเทศ | D18: Govern (GV) | E18: Policy (GV.PO) | F18: T1 | G18: Policy | H18: Organizational | I18: Essential | J18: Required | K18: ISO 27001 | L18: ISO/IEC 27001:2022 Clause 5.2 (documented information); PDPC Notification on Security Measures B.E. 2565 | M18: Expected | N18: GV.PO-01, GV.PO-02 | O18: 5.2, A.5.1 | P18: PM-1, PL-1 | Q18: Chief Information Security Officer (CISO) or Security Manager | R18: Chief Executive Officer (CEO) | S18: Annual | T18: GV-CHR-001 | U18: GV-POL-002, GV-STD-001, GV-PRC-002, GV-POL-003, GV-PRC-003, GV-POL-004, GV-POL-006, ID-STD-001, ID-STD-002, ID-PRC-006, PR-POL-001, PR-POL-002, PR-PLN-001, PR-POL-003, PR-STD-010, PR-PRC-006, PR-STD-011, PR-STD-012, PR-STD-013, PR-STD-015, PR-STD-016, DE-STD-001, RS-PLN-001 | V18: Governance | W18: 5 | X18: W0 Mandate and Mobilize | Y18: Track A | Z18: Specialist-guided | AA18: Cybersecurity consultant (project) / Security FTE | AB18: ACT-03 Legal and Regulatory Applicability Review; ACT-13 Policy Drafting and Stakeholder Review Cycle; ACT-14 Policy Approval and Communication | AC18: GV-CHR-001, GV-REG-001 | AD18: 02_Template_EN/01_GV_Govern/GV.PO_Policy/GV-POL-001_Information-Security-Policy.docx | AE18: Not started
A19: GV-PRC-002 | B19: Document Control Procedure | C19: ระเบียบปฏิบัติการควบคุมเอกสาร | D19: Govern (GV) | E19: Policy (GV.PO) | F19: T3 | G19: Procedure | H19: Organizational | I19: Essential | J19: Expected | K19: ISO 27001 | L19: ISO/IEC 27001:2022 Clause 7.5 (control of documented information; a procedure is not mandated) | M19: Expected | N19: GV.PO-02 | O19: 7.5, A.5.37 | P19: PL-1, PM-1 | Q19: Chief Information Security Officer (CISO) or Security Manager | R19: Chief Information Officer (CIO) | S19: Annual | T19: GV-POL-001 | V19: Process | W19: 6 | X19: W0 Mandate and Mobilize | Y19: Track A | Z19: IT-ready | AA19: In-house IT | AB19: ACT-14 Policy Approval and Communication | AC19: GV-POL-001 | AD19: 02_Template_EN/01_GV_Govern/GV.PO_Policy/GV-PRC-002_Document-Control-Procedure.docx | AE19: Not started
A20: GV-POL-003 | B20: Acceptable Use Policy | C20: นโยบายการใช้งานทรัพย์สินสารสนเทศที่ยอมรับได้ | D20: Govern (GV) | E20: Policy (GV.PO) | F20: T1 | G20: Policy | H20: Organizational | I20: Essential | J20: Expected | K20: All | L20: ISO/IEC 27001:2022 Annex A 5.10, 6.7, and 7.7 | M20: Expected | N20: GV.PO-01, PR.AT-01 | O20: A.5.10, A.6.7, A.7.7 | P20: PL-4 | Q20: Chief Information Security Officer (CISO) or Security Manager | R20: Chief Executive Officer (CEO) | S20: Annual | T20: GV-POL-001 | U20: GV-POL-005, PR-STD-009 | V20: People | W20: 45 | X20: W2 Direct | Y20: Track A | Z20: IT-ready | AA20: In-house IT / Human Resources | AB20: ACT-13 Policy Drafting and Stakeholder Review Cycle; ACT-14 Policy Approval and Communication | AC20: GV-POL-001 | AD20: 02_Template_EN/01_GV_Govern/GV.PO_Policy/GV-POL-003_Acceptable-Use-Policy.docx | AE20: Not started
A21: GV-POL-005 | B21: Generative AI Acceptable Use Policy | C21: นโยบายการใช้งาน Generative AI | D21: Govern (GV) | E21: Policy (GV.PO) | F21: T1 | G21: Policy | H21: Organizational | I21: Extended | J21: Optional | K21: All | L21: NIST AI RMF 1.0; NIST AI 600-1 (Generative AI Profile) | M21: Optional | N21: GV.PO-01, GV.OC-03, PR.DS-10 | O21: A.5.10 | P21: PL-4 | Q21: Chief Information Security Officer (CISO) or Security Manager | R21: Chief Executive Officer (CEO) | S21: Annual | T21: GV-POL-003 | V21: People, AI | W21: 135 | X21: W5 Optimize | Y21: Track A | Z21: Specialist-guided | AA21: Security FTE / Cybersecurity consultant (project) | AB21: ACT-13 Policy Drafting and Stakeholder Review Cycle; ACT-14 Policy Approval and Communication | AC21: GV-POL-003 | AD21: 02_Template_EN/01_GV_Govern/GV.PO_Policy/GV-POL-005_Generative-AI-Acceptable-Use-Policy.docx | AE21: Not started
A22: GV-PRC-003 | B22: Policy Exception Management Procedure | C22: ระเบียบปฏิบัติการขอยกเว้นการปฏิบัติตามนโยบาย | D22: Govern (GV) | E22: Policy (GV.PO) | F22: T3 | G22: Procedure | H22: Organizational | I22: Essential | J22: Expected | K22: All | L22: ISO/IEC 27001:2022 Annex A 5.36 | M22: Expected | N22: GV.PO-02, ID.RA-07 | O22: A.5.36 | P22: PL-1, RA-7 | Q22: Chief Information Security Officer (CISO) or Security Manager | R22: Chief Information Officer (CIO) | S22: Annual | T22: GV-POL-001 | U22: GV-FRM-004, GV-REG-004 | V22: Process | W22: 55 | X22: W2 Direct | Y22: Track A | Z22: IT-ready | AA22: In-house IT | AC22: GV-POL-001 | AD22: 02_Template_EN/01_GV_Govern/GV.PO_Policy/GV-PRC-003_Policy-Exception-Management-Procedure.docx | AE22: Not started
A23: GV-FRM-004 | B23: Policy Exception Request Form | C23: แบบฟอร์มขอยกเว้นการปฏิบัติตามนโยบาย | D23: Govern (GV) | E23: Policy (GV.PO) | F23: T4 | G23: Form | H23: Organizational | I23: Core | J23: Expected | K23: All | L23: ISO/IEC 27001:2022 Annex A 5.36 | M23: Expected | N23: ID.RA-07 | O23: A.5.36 | P23: RA-7 | Q23: Chief Information Security Officer (CISO) or Security Manager | R23: Chief Information Officer (CIO) | S23: Annual | T23: GV-PRC-003 | V23: Process, Evidence | W23: 56 | X23: W2 Direct | Y23: Track A | Z23: IT-ready | AA23: In-house IT | AC23: GV-PRC-003 | AD23: 02_Template_EN/01_GV_Govern/GV.PO_Policy/GV-FRM-004_Policy-Exception-Request-Form.docx | AE23: Not started
A24: GV-REG-004 | B24: Policy Exception Register | C24: ทะเบียนข้อยกเว้นการปฏิบัติตามนโยบาย | D24: Govern (GV) | E24: Policy (GV.PO) | F24: T4 | G24: Register | H24: Organizational | I24: Core | J24: Expected | K24: All | L24: ISO/IEC 27001:2022 Annex A 5.36 | M24: Expected | N24: ID.RA-07, GV.OV-02 | O24: A.5.36 | P24: RA-7, PM-4 | Q24: Chief Information Security Officer (CISO) or Security Manager | R24: Information Security Steering Committee (ISSC) | S24: Quarterly | T24: GV-PRC-003 | V24: Process, Evidence | W24: 57 | X24: W2 Direct | Y24: Track A | Z24: IT-ready | AA24: In-house IT | AC24: GV-PRC-003 | AD24: 02_Template_EN/01_GV_Govern/GV.PO_Policy/GV-REG-004_Policy-Exception-Register.docx | AE24: Not started
A25: GV-REG-005 | B25: Statement of Applicability (SoA) | C25: เอกสารแสดงการนำมาตรการควบคุมไปใช้ (SoA) | D25: Govern (GV) | E25: Policy (GV.PO) | F25: T4 | G25: Register | H25: Organizational | I25: Extended | J25: Required | K25: ISO 27001 | L25: ISO/IEC 27001:2022 Clause 6.1.3(d) | M25: Expected | N25: GV.PO-01, GV.RM-06 | O25: 6.1.3 | P25: PL-2 | Q25: Chief Information Security Officer (CISO) or Security Manager | R25: Information Security Steering Committee (ISSC) | S25: Annual | T25: GV-PRC-001 | V25: Governance, Evidence | W25: 42 | X25: W2 Direct | Y25: Track A | Z25: Specialist-required | AA25: Cybersecurity consultant (project) / Security FTE | AB25: ACT-11 Current State Assessment and CSF Profile Gap Analysis | AC25: ID-PLN-001, GV-RPT-001 | AD25: 02_Template_EN/01_GV_Govern/GV.PO_Policy/GV-REG-005_Statement-of-Applicability-SoA.docx | AE25: Not started
A26: GV-REG-006 | B26: CII Code of Practice Compliance Matrix | C26: ตารางการปฏิบัติตามประมวลแนวทางปฏิบัติสำหรับหน่วยงานโครงสร้างพื้นฐานสำคัญทางสารสนเทศ (CII) | D26: Govern (GV) | E26: Policy (GV.PO) | F26: T4 | G26: Register | H26: Organizational | I26: Extended | J26: Required | K26: CII | L26: CSA s.44; NCSC Notification on Code of Practice and Standard Framework B.E. 2564; CRC Notification on CII duties 2024 [VERIFY] | M26: Required | N26: GV.OC-03, GV.PO-01 | O26: A.5.31 | P26: PM-1 | Q26: Chief Information Security Officer (CISO) or Security Manager | R26: Information Security Steering Committee (ISSC) | S26: Annual | T26: GV-REG-001 | V26: Governance, Legal and Regulatory, Evidence | W26: 43 | X26: W2 Direct | Y26: Track A | Z26: Specialist-required | AA26: Cybersecurity consultant (project) / Legal counsel | AB26: ACT-03 Legal and Regulatory Applicability Review; ACT-11 Current State Assessment and CSF Profile Gap Analysis | AC26: GV-REG-001 | AD26: 02_Template_EN/01_GV_Govern/GV.PO_Policy/GV-REG-006_CII-Code-of-Practice-Compliance-Matrix.docx | AE26: Not started
A27: GV-POL-004 | B27: Personal Data Protection Policy | C27: นโยบายการคุ้มครองข้อมูลส่วนบุคคล | D27: Govern (GV) | E27: Policy (GV.PO) | F27: T1 | G27: Policy | H27: Organizational | I27: Essential | J27: Expected | K27: PDPA | L27: PDPA s.37(1); PDPC Notification on Security Measures B.E. 2565 | M27: Expected | N27: GV.OC-03, GV.PO-01 | O27: A.5.34 | P27: PT-1 | Q27: Data Protection Officer (DPO) | R27: Chief Executive Officer (CEO) | S27: Annual | T27: GV-POL-001 | U27: GV-REG-007, GV-TPL-002, GV-PRC-004, GV-PRC-005, GV-TPL-004, RS-PLB-003 | V27: Governance, Legal and Regulatory, Privacy | W27: 24 | X27: W1 Understand | Y27: Track A | Z27: Specialist-guided | AA27: DPO or privacy counsel service / Legal counsel | AB27: ACT-03 Legal and Regulatory Applicability Review; ACT-13 Policy Drafting and Stakeholder Review Cycle; ACT-14 Policy Approval and Communication | AC27: GV-REG-001, GV-POL-001 | AD27: 02_Template_EN/01_GV_Govern/GV.PO_Policy/GV-POL-004_Personal-Data-Protection-Policy.docx | AE27: Not started
A28: GV-REG-007 | B28: Record of Processing Activities (ROPA) | C28: บันทึกรายการกิจกรรมการประมวลผลข้อมูลส่วนบุคคล (ROPA) | D28: Govern (GV) | E28: Policy (GV.PO) | F28: T4 | G28: Register | H28: Organizational | I28: Essential | J28: Required | K28: PDPA | L28: PDPA s.39 (controller) and s.40 (processor) | M28: Required | N28: GV.OC-03, ID.AM-07 | O28: A.5.34 | P28: PT-2, PT-3 | Q28: Data Protection Officer (DPO) | R28: Data Protection Officer (DPO) | S28: Annual and on change | T28: GV-POL-004 | V28: Process, Legal and Regulatory, Privacy, Evidence | W28: 25 | X28: W1 Understand | Y28: Track A | Z28: Specialist-guided | AA28: DPO or privacy counsel service | AB28: ACT-06 Data Mapping Interviews | AC28: ID-REG-003 | AD28: 02_Template_EN/01_GV_Govern/GV.PO_Policy/GV-REG-007_Record-of-Processing-Activities-ROPA.docx | AE28: Not started
A29: GV-TPL-002 | B29: Privacy Notice Template | C29: แม่แบบประกาศความเป็นส่วนตัว | D29: Govern (GV) | E29: Policy (GV.PO) | F29: T4 | G29: Template | H29: Organizational | I29: Essential | J29: Required | K29: PDPA | L29: PDPA s.23 | M29: Required | N29: GV.OC-03 | O29: A.5.34 | P29: PT-5 | Q29: Data Protection Officer (DPO) | R29: Legal Counsel | S29: Annual | T29: GV-POL-004 | V29: Process, Legal and Regulatory, Privacy, Evidence | W29: 26 | X29: W1 Understand | Y29: Track A | Z29: Specialist-guided | AA29: DPO or privacy counsel service / Legal counsel | AB29: ACT-06 Data Mapping Interviews | AC29: GV-REG-007 | AD29: 02_Template_EN/01_GV_Govern/GV.PO_Policy/GV-TPL-002_Privacy-Notice-Template.docx | AE29: Not started
A30: GV-PRC-004 | B30: Data Protection Impact Assessment (DPIA) Procedure | C30: ระเบียบปฏิบัติการประเมินผลกระทบด้านการคุ้มครองข้อมูลส่วนบุคคล (DPIA) | D30: Govern (GV) | E30: Policy (GV.PO) | F30: T3 | G30: Procedure | H30: Organizational | I30: Core | J30: Expected | K30: PDPA | L30: Not explicitly mandated by the PDPA; supports the risk-based measures in PDPA s.37(1) [VERIFY current PDPC guidance] | M30: Expected | N30: GV.OC-03, ID.RA-04 | O30: A.5.34 | P30: RA-8 | Q30: Data Protection Officer (DPO) | R30: Information Security Steering Committee (ISSC) | S30: Annual | T30: GV-POL-004 | U30: GV-TPL-003 | V30: Process, Legal and Regulatory, Privacy | W30: 61 | X30: W2 Direct | Y30: Track A | Z30: Specialist-guided | AA30: DPO or privacy counsel service | AB30: ACT-13 Policy Drafting and Stakeholder Review Cycle | AC30: GV-POL-004 | AD30: 02_Template_EN/01_GV_Govern/GV.PO_Policy/GV-PRC-004_Data-Protection-Impact-Assessment-DPIA-Procedure.docx | AE30: Not started
A31: GV-TPL-003 | B31: DPIA Template | C31: แม่แบบการประเมินผลกระทบด้านการคุ้มครองข้อมูลส่วนบุคคล (DPIA) | D31: Govern (GV) | E31: Policy (GV.PO) | F31: T4 | G31: Template | H31: Organizational | I31: Core | J31: Expected | K31: PDPA | L31: Supports PDPA s.37(1) | M31: Expected | N31: ID.RA-04 | O31: A.5.34 | P31: RA-8 | Q31: Data Protection Officer (DPO) | R31: Data Protection Officer (DPO) | S31: Annual | T31: GV-PRC-004 | V31: Process, Legal and Regulatory, Privacy, Evidence | W31: 62 | X31: W2 Direct | Y31: Track A | Z31: Specialist-guided | AA31: DPO or privacy counsel service | AB31: ACT-27 Data Protection Impact Assessment (DPIA) Workshop | AC31: GV-PRC-004 | AD31: 02_Template_EN/01_GV_Govern/GV.PO_Policy/GV-TPL-003_DPIA-Template.docx | AE31: Not started
A32: GV-PRC-005 | B32: Data Subject Rights Request Procedure | C32: ระเบียบปฏิบัติการจัดการคำขอใช้สิทธิของเจ้าของข้อมูลส่วนบุคคล | D32: Govern (GV) | E32: Policy (GV.PO) | F32: T3 | G32: Procedure | H32: Organizational | I32: Essential | J32: Expected | K32: PDPA | L32: PDPA s.30 to s.36 (data subject rights; 30-day response under s.30) | M32: Expected | N32: GV.OC-03 | O32: A.5.34 | P32: PT-1 | Q32: Data Protection Officer (DPO) | R32: Information Security Steering Committee (ISSC) | S32: Annual | T32: GV-POL-004 | U32: GV-FRM-005 | V32: Process, Legal and Regulatory, Privacy | W32: 59 | X32: W2 Direct | Y32: Track A | Z32: Specialist-guided | AA32: DPO or privacy counsel service | AB32: ACT-13 Policy Drafting and Stakeholder Review Cycle | AC32: GV-POL-004 | AD32: 02_Template_EN/01_GV_Govern/GV.PO_Policy/GV-PRC-005_Data-Subject-Rights-Request-Procedure.docx | AE32: Not started
A33: GV-FRM-005 | B33: Data Subject Request Form | C33: แบบคำขอใช้สิทธิของเจ้าของข้อมูลส่วนบุคคล | D33: Govern (GV) | E33: Policy (GV.PO) | F33: T4 | G33: Form | H33: Organizational | I33: Core | J33: Expected | K33: PDPA | L33: PDPA s.30 to s.36 | M33: Expected | N33: GV.OC-03 | O33: A.5.34 | P33: PT-1 | Q33: Data Protection Officer (DPO) | R33: Data Protection Officer (DPO) | S33: Annual | T33: GV-PRC-005 | V33: Process, Legal and Regulatory, Privacy, Evidence | W33: 60 | X33: W2 Direct | Y33: Track A | Z33: IT-ready | AA33: In-house IT | AC33: GV-PRC-005 | AD33: 02_Template_EN/01_GV_Govern/GV.PO_Policy/GV-FRM-005_Data-Subject-Request-Form.docx | AE33: Not started
A34: GV-TPL-004 | B34: Data Processing Agreement Template | C34: แม่แบบข้อตกลงการประมวลผลข้อมูลส่วนบุคคล (DPA) | D34: Govern (GV) | E34: Policy (GV.PO) | F34: T4 | G34: Template | H34: Organizational | I34: Essential | J34: Required | K34: PDPA | L34: PDPA s.40; PDPC Notification on Security Measures B.E. 2565 (processor agreement) | M34: Required | N34: GV.SC-05, GV.OC-03 | O34: A.5.20, A.5.34 | P34: SA-9, PT-1 | Q34: Data Protection Officer (DPO) | R34: Legal Counsel | S34: Annual | T34: GV-POL-004, GV-STD-002 | V34: Process, Legal and Regulatory, Privacy, Evidence, Third Party | W34: 58 | X34: W2 Direct | Y34: Track A | Z34: Specialist-guided | AA34: Legal counsel / DPO or privacy counsel service | AC34: GV-POL-004 | AD34: 02_Template_EN/01_GV_Govern/GV.PO_Policy/GV-TPL-004_Data-Processing-Agreement-Template.docx | AE34: Not started
A35: GV-PRC-006 | B35: Management Review Procedure | C35: ระเบียบปฏิบัติการทบทวนโดยฝ่ายบริหาร | D35: Govern (GV) | E35: Oversight (GV.OV) | F35: T3 | G35: Procedure | H35: Organizational | I35: Core | J35: Expected | K35: ISO 27001 | L35: ISO/IEC 27001:2022 Clause 9.3 | M35: Expected | N35: GV.OV-01, GV.OV-02, GV.OV-03 | O35: 9.3 | P35: PM-6, PM-9 | Q35: Chief Information Security Officer (CISO) or Security Manager | R35: Information Security Steering Committee (ISSC) | S35: Annual | T35: GV-CHR-002 | U35: GV-REC-001 | V35: Governance | W35: 122 | X35: W4 Operate and Prove | Y35: Track A | Z35: Specialist-guided | AA35: Security FTE / Cybersecurity consultant (project) | AB35: ACT-24 Management Review Meeting | AC35: GV-CHR-002 | AD35: 02_Template_EN/01_GV_Govern/GV.OV_Oversight/GV-PRC-006_Management-Review-Procedure.docx | AE35: Not started
A36: GV-REC-001 | B36: Management Review Minutes | C36: บันทึกการประชุมทบทวนโดยฝ่ายบริหาร | D36: Govern (GV) | E36: Oversight (GV.OV) | F36: T4 | G36: Record | H36: Organizational | I36: Core | J36: Required | K36: ISO 27001 | L36: ISO/IEC 27001:2022 Clause 9.3.3 (results of management reviews) | M36: Expected | N36: GV.OV-01, GV.OV-02 | O36: 9.3 | P36: PM-9 | Q36: Chief Information Security Officer (CISO) or Security Manager | R36: Information Security Steering Committee (ISSC) | S36: Each meeting | T36: GV-PRC-006 | V36: Governance, Evidence | W36: 123 | X36: W4 Operate and Prove | Y36: Track A | Z36: IT-ready | AA36: In-house IT | AB36: ACT-24 Management Review Meeting | AC36: GV-PRC-006 | AD36: 02_Template_EN/01_GV_Govern/GV.OV_Oversight/GV-REC-001_Management-Review-Minutes.docx | AE36: Not started
A37: GV-REG-008 | B37: Cybersecurity Metrics Catalog (KPI and KRI) | C37: บัญชีตัวชี้วัดผลการดำเนินงานและตัวชี้วัดความเสี่ยงด้านไซเบอร์ (KPI และ KRI) | D37: Govern (GV) | E37: Oversight (GV.OV) | F37: T4 | G37: Register | H37: Organizational | I37: Core | J37: Required | K37: ISO 27001 | L37: ISO/IEC 27001:2022 Clause 9.1 (documented evidence of monitoring and measurement results; the catalog records definitions and results) | M37: Expected | N37: GV.OV-03, ID.IM-01 | O37: 9.1 | P37: PM-6, CA-7 | Q37: Chief Information Security Officer (CISO) or Security Manager | R37: Information Security Steering Committee (ISSC) | S37: Annual | T37: GV-STR-001 | U37: GV-TPL-005 | V37: Governance, Evidence | W37: 44 | X37: W2 Direct | Y37: Track A | Z37: Specialist-guided | AA37: Security FTE / Cybersecurity consultant (project) | AB37: ACT-12 Strategy, Roadmap, and Budget Planning Session | AC37: GV-STR-001 | AD37: 02_Template_EN/01_GV_Govern/GV.OV_Oversight/GV-REG-008_Cybersecurity-Metrics-Catalog-KPI-and-KRI.docx | AE37: Not started
A38: GV-TPL-005 | B38: Board Cybersecurity Report Template | C38: แม่แบบรายงานด้านความมั่นคงปลอดภัยไซเบอร์ต่อคณะกรรมการ | D38: Govern (GV) | E38: Oversight (GV.OV) | F38: T4 | G38: Template | H38: Organizational | I38: Core | J38: Expected | K38: All | L38: Common practice; NIST IR 8286 series | M38: Expected | N38: GV.OV-01, GV.OV-03 | O38: 9.1, 9.3 | P38: PM-6 | Q38: Chief Information Security Officer (CISO) or Security Manager | R38: Chief Executive Officer (CEO) | S38: Annual | T38: GV-REG-008 | V38: Governance, Evidence | W38: 98 | X38: W3 Standardize | Y38: Track A | Z38: Specialist-guided | AA38: Security FTE / Cybersecurity consultant (project) | AC38: GV-REG-008 | AD38: 02_Template_EN/01_GV_Govern/GV.OV_Oversight/GV-TPL-005_Board-Cybersecurity-Report-Template.docx | AE38: Not started
A39: GV-PRC-007 | B39: Internal Audit Procedure | C39: ระเบียบปฏิบัติการตรวจสอบภายในด้านความมั่นคงปลอดภัยสารสนเทศ | D39: Govern (GV) | E39: Oversight (GV.OV) | F39: T3 | G39: Procedure | H39: Organizational | I39: Core | J39: Expected | K39: ISO 27001, CII | L39: ISO/IEC 27001:2022 Clause 9.2; CSA s.54 | M39: Expected | N39: GV.OV-02, ID.IM-01 | O39: 9.2, A.5.35 | P39: CA-2, CA-7 | Q39: Head of Internal Audit | R39: Audit Committee | S39: Annual | T39: GV-CHR-001 | U39: GV-PLN-002, GV-TPL-006 | V39: Governance, Legal and Regulatory | W39: 124 | X39: W4 Operate and Prove | Y39: Track A | Z39: Specialist-required | AA39: Co-sourced internal audit | AB39: ACT-25 Internal Audit Planning and Fieldwork | AC39: GV-CHR-001 | AD39: 02_Template_EN/01_GV_Govern/GV.OV_Oversight/GV-PRC-007_Internal-Audit-Procedure.docx | AE39: Not started
A40: GV-PLN-002 | B40: Internal Audit Program | C40: แผนการตรวจสอบภายในประจำปี | D40: Govern (GV) | E40: Oversight (GV.OV) | F40: T3 | G40: Plan | H40: Organizational | I40: Core | J40: Required | K40: ISO 27001, CII | L40: ISO/IEC 27001:2022 Clause 9.2.2 (audit program); CSA s.54 (annual audit) | M40: Required | N40: GV.OV-02 | O40: 9.2 | P40: CA-2 | Q40: Head of Internal Audit | R40: Audit Committee | S40: Annual | T40: GV-PRC-007 | V40: Governance, Legal and Regulatory | W40: 125 | X40: W4 Operate and Prove | Y40: Track A | Z40: Specialist-required | AA40: Co-sourced internal audit | AB40: ACT-25 Internal Audit Planning and Fieldwork | AC40: GV-PRC-007 | AD40: 02_Template_EN/01_GV_Govern/GV.OV_Oversight/GV-PLN-002_Internal-Audit-Program.docx | AE40: Not started
...

Sheet Implementation Roadmap
A1: Build Order | B1: Wave | C1: Wave Name | D1: Timing | E1: Track | F1: Document ID | G1: Title | H1: Level | I1: Capability | J1: Why | K1: Sourcing Options | L1: Prerequisite Activities | M1: Depends On | N1: Unlocks | O1: Interim: Align Later To | P1: Advice
A2: 1 | B2: W0 | C2: Mandate and Mobilize | D2: Month 0 to 2 | E2: Track A: Governance build | F2: GV-CHR-001 | G2: Cybersecurity Governance Charter | H2: Expected | I2: Specialist-guided | J2: Needs neutral facilitation of executive or cross-department decisions. | K2: In-house IT / Cybersecurity consultant (project) | L2: ACT-01 Executive Kickoff and Mandate Meeting; ACT-02 Governance Structure and RACI Workshop | N2: GV-CHR-002, GV-POL-001, GV-RPT-001, GV-STM-001, RC-POL-001, GV-PRC-007
A3: 2 | B3: W0 | C3: Mandate and Mobilize | D3: Month 0 to 2 | E3: Track A: Governance build | F3: GV-CHR-002 | G3: Information Security Steering Committee Terms of Reference | H3: Expected | I3: IT-ready | J3: Template-driven: content is mostly factual or administrative. | K3: In-house IT | L3: ACT-02 Governance Structure and RACI Workshop | M3: GV-CHR-001 | N3: GV-REG-003, GV-PRC-006
A4: 3 | B4: W0 | C4: Mandate and Mobilize | D4: Month 0 to 2 | E4: Track A: Governance build | F4: GV-REG-003 | G4: Cybersecurity Roles, Responsibilities, and RACI Matrix | H4: Expected | I4: Specialist-guided | J4: Needs neutral facilitation of executive or cross-department decisions. | K4: In-house IT / Cybersecurity consultant (project) | L4: ACT-02 Governance Structure and RACI Workshop | M4: GV-CHR-002 | N4: GV-TPL-001
A5: 4 | B5: W0 | C5: Mandate and Mobilize | D5: Month 0 to 2 | E5: Track A: Governance build | F5: GV-REG-001 | G5: Legal, Regulatory, and Contractual Requirements Register | H5: Expected | I5: Specialist-required | J5: Needs interpretation of Thai cybersecurity, PDPA, or contract obligations. | K5: Legal counsel / Cybersecurity consultant (project) | L5: ACT-03 Legal and Regulatory Applicability Review | N5: GV-POL-001, GV-RPT-001, GV-POL-004, GV-REG-006, PR-STD-011, RS-PRC-003 | O5: GV-RPT-001
A6: 5 | B6: W0 | C6: Mandate and Mobilize | D6: Month 0 to 2 | E6: Track A: Governance build | F6: GV-POL-001 | G6: Information Security Policy | H6: Required | I6: Specialist-guided | J6: Needs neutral facilitation of executive or cross-department decisions. Needs interpretation of Thai cybersecurity, PDPA, or contract obligations. | K6: Cybersecurity consultant (project) / Security FTE | L6: ACT-03 Legal and Regulatory Applicability Review; ACT-13 Policy Drafting and Stakeholder Review Cycle; ACT-14 Policy Approval and Communication | M6: GV-CHR-001, GV-REG-001 | N6: GV-PRC-002, ID-STD-001, GV-POL-004, GV-POL-002, GV-POL-003, PR-POL-001, PR-POL-003, GV-POL-006, PR-POL-002, GV-STD-001, GV-PRC-003, ID-STD-002, PR-PRC-006, PR-STD-013, ID-PRC-006 | P6: Issue a short umbrella policy early. Topic policies follow once the risk picture is known.
A7: 6 | B7: W0 | C7: Mandate and Mobilize | D7: Month 0 to 2 | E7: Track A: Governance build | F7: GV-PRC-002 | G7: Document Control Procedure | H7: Expected | I7: IT-ready | J7: Template-driven: content is mostly factual or administrative. | K7: In-house IT | L7: ACT-14 Policy Approval and Communication | M7: GV-POL-001
A8: 7 | B8: W0 | C8: Mandate and Mobilize | D8: Month 0 to 2 | E8: Track B: Threat-driven quick wins (Day 0 to 90) | F8: RS-REG-002 | G8: Incident Response Contact List | H8: Required | I8: IT-ready | J8: Template-driven: content is mostly factual or administrative. | K8: In-house IT | N8: RS-PLN-001
A9: 8 | B9: W0 | C9: Mandate and Mobilize | D9: Month 0 to 2 | E9: Track B: Threat-driven quick wins (Day 0 to 90) | F9: RS-PLN-001 | G9: Cybersecurity Incident Response Plan | H9: Required | I9: Specialist-required | J9: Needs incident handling and digital forensics experience. Needs interpretation of Thai cybersecurity, PDPA, or contract obligations. | K9: Incident response retainer / Cybersecurity consultant (project) | L9: ACT-17 Incident Response Readiness Workshop | M9: RS-REG-002 | N9: RS-FRM-001, RS-REG-001, RS-PLB-001, DE-STD-002, RS-PRC-001, RS-PRC-002, RS-PRC-003, ID-PLN-002 | P9: Start with a 5 to 10 page interim plan in the first 30 days. Expand it in Wave 3 once severity levels and procedures exist.
A10: 9 | B10: W0 | C10: Mandate and Mobilize | D10: Month 0 to 2 | E10: Track B: Threat-driven quick wins (Day 0 to 90) | F10: RS-FRM-001 | G10: Incident Report Form | H10: Expected | I10: IT-ready | J10: Template-driven: content is mostly factual or administrative. | K10: In-house IT | M10: RS-PLN-001 | O10: RS-PRC-001
A11: 10 | B11: W0 | C11: Mandate and Mobilize | D11: Month 0 to 2 | E11: Track B: Threat-driven quick wins (Day 0 to 90) | F11: RS-REG-001 | G11: Incident Register | H11: Expected | I11: IT-ready | J11: Template-driven: content is mostly factual or administrative. | K11: In-house IT | M11: RS-PLN-001 | O11: RS-PRC-001
A12: 11 | B12: W0 | C12: Mandate and Mobilize | D12: Month 0 to 2 | E12: Track B: Threat-driven quick wins (Day 0 to 90) | F12: PR-STD-006 | G12: Backup Standard | H12: Expected | I12: IT-ready | J12: Template-driven: content is mostly factual or administrative. | K12: In-house IT | L12: ACT-18 Backup and Restore Validation Test | N12: PR-PRC-005 | O12: PR-POL-003
A13: 12 | B13: W0 | C13: Mandate and Mobilize | D13: Month 0 to 2 | E13: Track B: Threat-driven quick wins (Day 0 to 90) | F13: PR-PRC-005 | G13: Backup and Restore Procedure | H13: Expected | I13: IT-ready | J13: Operational: IT runs it day to day once the parent standard exists. | K13: In-house IT | L13: ACT-18 Backup and Restore Validation Test | M13: PR-STD-006 | N13: PR-REC-003, RS-PLB-001
A14: 13 | B14: W0 | C14: Mandate and Mobilize | D14: Month 0 to 2 | E14: Track B: Threat-driven quick wins (Day 0 to 90) | F14: PR-REC-003 | G14: Backup and Restore Test Record | H14: Expected | I14: IT-ready | J14: Operational: IT runs it day to day once the parent standard exists. | K14: In-house IT | L14: ACT-18 Backup and Restore Validation Test | M14: PR-PRC-005
A15: 14 | B15: W0 | C15: Mandate and Mobilize | D15: Month 0 to 2 | E15: Track B: Threat-driven quick wins (Day 0 to 90) | F15: PR-STD-001 | G15: Identity and Authentication Standard | H15: Expected | I15: Specialist-guided | J15: Needs security architecture judgment to set technical requirements. | K15: In-house IT / Cybersecurity consultant (project) | L15: ACT-19 Identity and Privileged Access Review | N15: PR-STD-002, PR-STD-003 | O15: PR-POL-001 | P15: Multi-factor authentication for remote access, email, and administrators is the first technical control to enforce.
A16: 15 | B16: W0 | C16: Mandate and Mobilize | D16: Month 0 to 2 | E16: Track B: Threat-driven quick wins (Day 0 to 90) | F16: PR-REG-001 | G16: Privileged Account Register | H16: Expected | I16: IT-ready | J16: Operational: IT runs it day to day once the parent standard exists. | K16: In-house IT | L16: ACT-19 Identity and Privileged Access Review | O16: PR-STD-002
A17: 16 | B17: W1 | C17: Understand | D17: Month 1 to 4 | E17: Track A: Governance build | F17: GV-RPT-001 | G17: Organizational Context and ISMS Scope Statement | H17: Required | I17: Specialist-guided | J17: Needs neutral facilitation of executive or cross-department decisions. | K17: Cybersecurity consultant (project) / Security FTE | L17: ACT-04 Scope and Organizational Context Workshop | M17: GV-CHR-001, GV-REG-001 | N17: GV-REG-002, GV-STR-001, GV-REG-005
A18: 17 | B18: W1 | C18: Understand | D18: Month 1 to 4 | E18: Track A: Governance build | F18: GV-REG-002 | G18: Stakeholder Requirements Register | H18: Expected | I18: IT-ready | J18: Template-driven: content is mostly factual or administrative. | K18: In-house IT | L18: ACT-04 Scope and Organizational Context Workshop | M18: GV-RPT-001
A19: 18 | B19: W1 | C19: Understand | D19: Month 1 to 4 | E19: Track A: Governance build | F19: ID-STD-001 | G19: Asset Management Standard | H19: Expected | I19: IT-ready | J19: Template-driven: content is mostly factual or administrative. | K19: In-house IT | L19: ACT-13 Policy Drafting and Stakeholder Review Cycle | M19: GV-POL-001 | N19: ID-PRC-001
A20: 19 | B20: W1 | C20: Understand | D20: Month 1 to 4 | E20: Track A: Governance build | F20: ID-REG-001 | G20: Hardware Asset Inventory | H20: Expected | I20: IT-ready | J20: Template-driven: content is mostly factual or administrative. Operational: IT runs it day to day once the parent standard exists. | K20: In-house IT | L20: ACT-05 Asset Discovery and Inventory Reconciliation | N20: ID-RPT-001, ID-REG-004, ID-RPT-002, ID-REG-005, PR-STD-012, PR-STD-010 | P20: Do not wait for the asset standard. Build the inventory now and formalize the rules later.
A21: 20 | B21: W1 | C21: Understand | D21: Month 1 to 4 | E21: Track A: Governance build | F21: ID-REG-002 | G21: Software and Service Inventory | H21: Expected | I21: IT-ready | J21: Template-driven: content is mostly factual or administrative. Operational: IT runs it day to day once the parent standard exists. | K21: In-house IT | L21: ACT-05 Asset Discovery and Inventory Reconciliation | N21: ID-REG-003, ID-RPT-002
A22: 21 | B22: W1 | C22: Understand | D22: Month 1 to 4 | E22: Track A: Governance build | F22: ID-RPT-001 | G22: Network Architecture and Data Flow Diagram | H22: Expected | I22: IT-ready | J22: Template-driven: content is mostly factual or administrative. | K22: In-house IT | L22: ACT-05 Asset Discovery and Inventory Reconciliation | M22: ID-REG-001 | N22: PR-STD-016
A23: 22 | B23: W1 | C23: Understand | D23: Month 1 to 4 | E23: Track A: Governance build | F23: ID-REG-004 | G23: OT and Medical Device Inventory | H23: Optional | I23: IT-ready | J23: Template-driven: content is mostly factual or administrative. | K23: In-house IT | L23: ACT-05 Asset Discovery and Inventory Reconciliation | M23: ID-REG-001 | N23: PR-STD-015
A24: 23 | B24: W1 | C24: Understand | D24: Month 1 to 4 | E24: Track A: Governance build | F24: ID-REG-003 | G24: Data Inventory and Data Flow Register | H24: Expected | I24: Specialist-guided | J24: Needs privacy expertise: PDPA lawful basis, DPIA, data subject rights. | K24: DPO or privacy counsel service / In-house IT | L24: ACT-06 Data Mapping Interviews | M24: ID-REG-002 | N24: GV-REG-007, PR-POL-003
A25: 24 | B25: W1 | C25: Understand | D25: Month 1 to 4 | E25: Track A: Governance build | F25: GV-POL-004 | G25: Personal Data Protection Policy | H25: Expected | I25: Specialist-guided | J25: Needs privacy expertise: PDPA lawful basis, DPIA, data subject rights. Needs interpretation of Thai cybersecurity, PDPA, or contract obligations. | K25: DPO or privacy counsel service / Legal counsel | L25: ACT-03 Legal and Regulatory Applicability Review; ACT-13 Policy Drafting and Stakeholder Review Cycle; ACT-14 Policy Approval and Communication | M25: GV-REG-001, GV-POL-001 | N25: GV-TPL-004, GV-PRC-005, GV-PRC-004, RS-PLB-003
A26: 25 | B26: W1 | C26: Understand | D26: Month 1 to 4 | E26: Track A: Governance build | F26: GV-REG-007 | G26: Record of Processing Activities (ROPA) | H26: Required | I26: Specialist-guided | J26: Needs privacy expertise: PDPA lawful basis, DPIA, data subject rights. | K26: DPO or privacy counsel service | L26: ACT-06 Data Mapping Interviews | M26: ID-REG-003 | N26: GV-TPL-002
A27: 26 | B27: W1 | C27: Understand | D27: Month 1 to 4 | E27: Track A: Governance build | F27: GV-TPL-002 | G27: Privacy Notice Template | H27: Required | I27: Specialist-guided | J27: Needs privacy expertise: PDPA lawful basis, DPIA, data subject rights. Needs interpretation of Thai cybersecurity, PDPA, or contract obligations. | K27: DPO or privacy counsel service / Legal counsel | L27: ACT-06 Data Mapping Interviews | M27: GV-REG-007
A28: 27 | B28: W1 | C28: Understand | D28: Month 1 to 4 | E28: Track A: Governance build | F28: GV-REG-009 | G28: Supplier Inventory and Criticality Register | H28: Expected | I28: IT-ready | J28: Template-driven: content is mostly factual or administrative. | K28: In-house IT | L28: ACT-16 Supplier Tiering Workshop | N28: GV-POL-006 | O28: GV-PRC-008
A29: 28 | B29: W1 | C29: Understand | D29: Month 1 to 4 | E29: Track A: Governance build | F29: ID-RPT-002 | G29: Business Impact Analysis (BIA) | H29: Expected | I29: Specialist-required | J29: Needs business continuity methodology (ISO 22301). Needs neutral facilitation of executive or cross-department decisions. | K29: Cybersecurity consultant (project) | L29: ACT-07 Business Impact Analysis (BIA) Interviews and Validation Workshop | M29: ID-REG-001, ID-REG-002 | N29: GV-STM-001, ID-REG-005, RC-POL-001, PR-STD-017, RC-PLN-001 | O29: RC-POL-001 | P29: BIA usually runs before the continuity policy is approved. Align it to RC-POL-001 when issued.
A30: 29 | B30: W1 | C30: Understand | D30: Month 1 to 4 | E30: Track A: Governance build | F30: GV-STM-001 | G30: Risk Appetite and Tolerance Statement | H30: Expected | I30: Specialist-required | J30: Needs neutral facilitation of executive or cross-department decisions. Needs risk methodology design and calibration skills. | K30: Cybersecurity consultant (project) | L30: ACT-08 Risk Appetite Workshop | M30: ID-RPT-002, GV-CHR-001 | N30: GV-POL-002
A31: 30 | B31: W1 | C31: Understand | D31: Month 1 to 4 | E31: Track A: Governance build | F31: GV-POL-002 | G31: Cybersecurity Risk Management Policy | H31: Expected | I31: Specialist-guided | J31: Needs risk methodology design and calibration skills. | K31: Cybersecurity consultant (project) / Security FTE | L31: ACT-13 Policy Drafting and Stakeholder Review Cycle; ACT-14 Policy Approval and Communication | M31: GV-POL-001, GV-STM-001 | N31: GV-PRC-001
A32: 31 | B32: W1 | C32: Understand | D32: Month 1 to 4 | E32: Track A: Governance build | F32: GV-PRC-001 | G32: Risk Assessment and Treatment Methodology | H32: Required | I32: Specialist-required | J32: Needs risk methodology design and calibration skills. | K32: Cybersecurity consultant (project) / Security FTE | L32: ACT-09 Risk Methodology Design and Calibration Session | M32: GV-POL-002 | N32: ID-REG-005, GV-FRM-001, ID-PRC-004
A33: 32 | B33: W1 | C33: Understand | D33: Month 1 to 4 | E33: Track A: Governance build | F33: ID-REG-005 | G33: IT and Cybersecurity Risk Register | H33: Required | I33: Specialist-required | J33: Needs risk methodology design and calibration skills. | K33: Cybersecurity consultant (project) / Security FTE | L33: ACT-10 Risk Assessment Workshops | M33: GV-PRC-001, ID-REG-001, ID-RPT-002 | N33: ID-RPT-003, ID-PLN-001, DE-STD-001
A34: 33 | B34: W1 | C34: Understand | D34: Month 1 to 4 | E34: Track A: Governance build | F34: ID-RPT-003 | G34: Cybersecurity Risk Assessment Report | H34: Required | I34: Specialist-required | J34: Needs risk methodology design and calibration skills. | K34: Cybersecurity consultant (project) / Security FTE | L34: ACT-10 Risk Assessment Workshops; ACT-11 Current State Assessment and CSF Profile Gap Analysis | M34: ID-REG-005 | N34: GV-STR-001
A35: 34 | B35: W1 | C35: Understand | D35: Month 1 to 4 | E35: Track B: Threat-driven quick wins (Day 0 to 90) | F35: RS-PLB-001 | G35: Ransomware Response Playbook | H35: Expected | I35: Specialist-required | J35: Needs incident handling and digital forensics experience. | K35: Incident response retainer / Cybersecurity consultant (project) | L35: ACT-17 Incident Response Readiness Workshop; ACT-20 Tabletop Exercise | M35: RS-PLN-001, PR-PRC-005 | O35: RS-PRC-001
A36: 35 | B36: W1 | C36: Understand | D36: Month 1 to 4 | E36: Track B: Threat-driven quick wins (Day 0 to 90) | F36: PR-STD-002 | G36: Privileged Access Management Standard | H36: Expected | I36: Specialist-guided | J36: Needs security architecture judgment to set technical requirements. | K36: In-house IT / Cybersecurity consultant (project) | L36: ACT-19 Identity and Privileged Access Review | M36: PR-STD-001 | N36: PR-FRM-002 | O36: PR-POL-001
A37: 36 | B37: W1 | C37: Understand | D37: Month 1 to 4 | E37: Track B: Threat-driven quick wins (Day 0 to 90) | F37: PR-STD-003 | G37: Remote Access Standard | H37: Expected | I37: Specialist-guided | J37: Needs security architecture judgment to set technical requirements. | K37: In-house IT / Cybersecurity consultant (project) | L37: ACT-19 Identity and Privileged Access Review | M37: PR-STD-001 | N37: PR-FRM-003 | O37: PR-POL-001
A38: 37 | B38: W1 | C38: Understand | D38: Month 1 to 4 | E38: Track B: Threat-driven quick wins (Day 0 to 90) | F38: PR-STD-012 | G38: Endpoint Protection Standard | H38: Expected | I38: Specialist-guided | J38: Needs security architecture judgment to set technical requirements. | K38: In-house IT / Managed Security Service Provider (MSSP) | M38: ID-REG-001 | N38: PR-REG-003
A39: 38 | B39: W2 | C39: Direct | D39: Month 3 to 7 | E39: Track A: Governance build | F39: GV-STR-001 | G39: Cybersecurity Strategy and Roadmap | H39: Required | I39: Specialist-guided | J39: Needs neutral facilitation of executive or cross-department decisions. | K39: Cybersecurity consultant (project) / Security FTE | L39: ACT-11 Current State Assessment and CSF Profile Gap Analysis; ACT-12 Strategy, Roadmap, and Budget Planning Session | M39: ID-RPT-003, GV-RPT-001 | N39: GV-PLN-001, GV-REG-008
A40: 39 | B40: W2 | C40: Direct | D40: Month 3 to 7 | E40: Track A: Governance build | F40: GV-PLN-001 | G40: Cybersecurity Budget and Resource Plan | H40: Expected | I40: Specialist-guided | J40: Needs neutral facilitation of executive or cross-department decisions. | K40: Security FTE / In-house IT | L40: ACT-12 Strategy, Roadmap, and Budget Planning Session | M40: GV-STR-001
...

Sheet Prerequisite Activities
A1: Activity ID | B1: Activity (EN) | C1: Activity (TH) | D1: Purpose | E1: Agenda | F1: Participants | G1: Inputs | H1: Duration | I1: Frequency | J1: Facilitator Capability | K1: First Time in This Organization | L1: Feeds Documents
A2: ACT-01 | B2: Executive Kickoff and Mandate Meeting | C2: ประชุม Kickoff ผู้บริหารและการมอบอำนาจหน้าที่ | D2: Secure executive sponsorship, agree why the organization is formalizing cybersecurity, and confirm who owns the program. | E2: 1. Trigger and business case: incidents in the sector, legal duties (CII, PDPA), customer demands 2. Program objectives for the first 12 months 3. Who sponsors, who owns, and who runs the program 4. Reporting line of the security lead and escalation route to the Board 5. Decisions needed: approve charter drafting, name the program owner, set the next meeting | F2: Chief Executive Officer (CEO), Chief Information Officer (CIO), Chief Financial Officer (CFO), Chief Information Security Officer (CISO) or Security Manager, Chief Risk Officer (CRO) or Enterprise Risk Manager, Legal Counsel | G2: Sector incident news, legal applicability notes | H2: 90 minutes | I2: One time | J2: Specialist-guided | K2: Keep it short and decision focused. Bring one page with three decisions only. Without a named sponsor, every later document will stall at approval. | L2: GV-CHR-001
