Workbook

Sheet Category Summary
A1: Function | B1: Category | C1: Category name | D1: Current Tier | E1: Target Tier | F1: Tier gap | G1: Feasibility flag | H1: Gaps | I1: Highest score | J1: Highest band | K1: IMPs
A2: Govern | B2: GV.OC | C2: Organizational Context | D2: 1 | E2: 3 | F2: =MAX(0,E2-D2) -> 2 | G2: =IF(F2>=2,"Yes","No") -> Yes | H2: =COUNTIF('Gap Register'!$C$2:$C$40,B2) -> 2 | I2: =_xlfn.MAXIFS('Gap Register'!$N$2:$N$40,'Gap Register'!$C$2:$C$40,B2) -> 12 | J2: =IF(H2=0,"None",IF(I2>=Notes!$B$7,"Critical",IF(I2>=Notes!$B$8,"High",IF(I2>=Notes!$B$9,"Medium","Low")))) -> High | K2: =COUNTIF('Improvement Actions'!$C$2:$C$73,B2) -> 3
A3: Govern | B3: GV.RM | C3: Risk Management Strategy | D3: 1 | E3: 3 | F3: =MAX(0,E3-D3) -> 2 | G3: =IF(F3>=2,"Yes","No") -> Yes | H3: =COUNTIF('Gap Register'!$C$2:$C$40,B3) -> 2 | I3: =_xlfn.MAXIFS('Gap Register'!$N$2:$N$40,'Gap Register'!$C$2:$C$40,B3) -> 16 | J3: =IF(H3=0,"None",IF(I3>=Notes!$B$7,"Critical",IF(I3>=Notes!$B$8,"High",IF(I3>=Notes!$B$9,"Medium","Low")))) -> High | K3: =COUNTIF('Improvement Actions'!$C$2:$C$73,B3) -> 3
A4: Govern | B4: GV.RR | C4: Roles, Responsibilities, and Authorities | D4: 1 | E4: 3 | F4: =MAX(0,E4-D4) -> 2 | G4: =IF(F4>=2,"Yes","No") -> Yes | H4: =COUNTIF('Gap Register'!$C$2:$C$40,B4) -> 2 | I4: =_xlfn.MAXIFS('Gap Register'!$N$2:$N$40,'Gap Register'!$C$2:$C$40,B4) -> 16 | J4: =IF(H4=0,"None",IF(I4>=Notes!$B$7,"Critical",IF(I4>=Notes!$B$8,"High",IF(I4>=Notes!$B$9,"Medium","Low")))) -> High | K4: =COUNTIF('Improvement Actions'!$C$2:$C$73,B4) -> 3
A5: Govern | B5: GV.PO | C5: Policy | D5: 1 | E5: 3 | F5: =MAX(0,E5-D5) -> 2 | G5: =IF(F5>=2,"Yes","No") -> Yes | H5: =COUNTIF('Gap Register'!$C$2:$C$40,B5) -> 2 | I5: =_xlfn.MAXIFS('Gap Register'!$N$2:$N$40,'Gap Register'!$C$2:$C$40,B5) -> 16 | J5: =IF(H5=0,"None",IF(I5>=Notes!$B$7,"Critical",IF(I5>=Notes!$B$8,"High",IF(I5>=Notes!$B$9,"Medium","Low")))) -> High | K5: =COUNTIF('Improvement Actions'!$C$2:$C$73,B5) -> 2
A6: Govern | B6: GV.OV | C6: Oversight | D6: 1 | E6: 3 | F6: =MAX(0,E6-D6) -> 2 | G6: =IF(F6>=2,"Yes","No") -> Yes | H6: =COUNTIF('Gap Register'!$C$2:$C$40,B6) -> 1 | I6: =_xlfn.MAXIFS('Gap Register'!$N$2:$N$40,'Gap Register'!$C$2:$C$40,B6) -> 9 | J6: =IF(H6=0,"None",IF(I6>=Notes!$B$7,"Critical",IF(I6>=Notes!$B$8,"High",IF(I6>=Notes!$B$9,"Medium","Low")))) -> Medium | K6: =COUNTIF('Improvement Actions'!$C$2:$C$73,B6) -> 1
A7: Govern | B7: GV.SC | C7: Cybersecurity Supply Chain Risk Management | D7: 1 | E7: 3 | F7: =MAX(0,E7-D7) -> 2 | G7: =IF(F7>=2,"Yes","No") -> Yes | H7: =COUNTIF('Gap Register'!$C$2:$C$40,B7) -> 2 | I7: =_xlfn.MAXIFS('Gap Register'!$N$2:$N$40,'Gap Register'!$C$2:$C$40,B7) -> 20 | J7: =IF(H7=0,"None",IF(I7>=Notes!$B$7,"Critical",IF(I7>=Notes!$B$8,"High",IF(I7>=Notes!$B$9,"Medium","Low")))) -> Critical | K7: =COUNTIF('Improvement Actions'!$C$2:$C$73,B7) -> 5
A8: Identify | B8: ID.AM | C8: Asset Management | D8: 1 | E8: 3 | F8: =MAX(0,E8-D8) -> 2 | G8: =IF(F8>=2,"Yes","No") -> Yes | H8: =COUNTIF('Gap Register'!$C$2:$C$40,B8) -> 2 | I8: =_xlfn.MAXIFS('Gap Register'!$N$2:$N$40,'Gap Register'!$C$2:$C$40,B8) -> 12 | J8: =IF(H8=0,"None",IF(I8>=Notes!$B$7,"Critical",IF(I8>=Notes!$B$8,"High",IF(I8>=Notes!$B$9,"Medium","Low")))) -> High | K8: =COUNTIF('Improvement Actions'!$C$2:$C$73,B8) -> 4
A9: Identify | B9: ID.RA | C9: Risk Assessment | D9: 1 | E9: 3 | F9: =MAX(0,E9-D9) -> 2 | G9: =IF(F9>=2,"Yes","No") -> Yes | H9: =COUNTIF('Gap Register'!$C$2:$C$40,B9) -> 2 | I9: =_xlfn.MAXIFS('Gap Register'!$N$2:$N$40,'Gap Register'!$C$2:$C$40,B9) -> 20 | J9: =IF(H9=0,"None",IF(I9>=Notes!$B$7,"Critical",IF(I9>=Notes!$B$8,"High",IF(I9>=Notes!$B$9,"Medium","Low")))) -> Critical | K9: =COUNTIF('Improvement Actions'!$C$2:$C$73,B9) -> 4
A10: Identify | B10: ID.IM | C10: Improvement | D10: 1 | E10: 3 | F10: =MAX(0,E10-D10) -> 2 | G10: =IF(F10>=2,"Yes","No") -> Yes | H10: =COUNTIF('Gap Register'!$C$2:$C$40,B10) -> 1 | I10: =_xlfn.MAXIFS('Gap Register'!$N$2:$N$40,'Gap Register'!$C$2:$C$40,B10) -> 12 | J10: =IF(H10=0,"None",IF(I10>=Notes!$B$7,"Critical",IF(I10>=Notes!$B$8,"High",IF(I10>=Notes!$B$9,"Medium","Low")))) -> High | K10: =COUNTIF('Improvement Actions'!$C$2:$C$73,B10) -> 2
A11: Protect | B11: PR.AA | C11: Identity Management, Authentication, and Access Control | D11: 2 | E11: 3 | F11: =MAX(0,E11-D11) -> 1 | G11: =IF(F11>=2,"Yes","No") -> No | H11: =COUNTIF('Gap Register'!$C$2:$C$40,B11) -> 2 | I11: =_xlfn.MAXIFS('Gap Register'!$N$2:$N$40,'Gap Register'!$C$2:$C$40,B11) -> 20 | J11: =IF(H11=0,"None",IF(I11>=Notes!$B$7,"Critical",IF(I11>=Notes!$B$8,"High",IF(I11>=Notes!$B$9,"Medium","Low")))) -> Critical | K11: =COUNTIF('Improvement Actions'!$C$2:$C$73,B11) -> 9
A12: Protect | B12: PR.AT | C12: Awareness and Training | D12: 2 | E12: 2 | F12: =MAX(0,E12-D12) -> 0 | G12: =IF(F12>=2,"Yes","No") -> No | H12: =COUNTIF('Gap Register'!$C$2:$C$40,B12) -> 1 | I12: =_xlfn.MAXIFS('Gap Register'!$N$2:$N$40,'Gap Register'!$C$2:$C$40,B12) -> 6 | J12: =IF(H12=0,"None",IF(I12>=Notes!$B$7,"Critical",IF(I12>=Notes!$B$8,"High",IF(I12>=Notes!$B$9,"Medium","Low")))) -> Medium | K12: =COUNTIF('Improvement Actions'!$C$2:$C$73,B12) -> 1
A13: Protect | B13: PR.DS | C13: Data Security | D13: 1 | E13: 3 | F13: =MAX(0,E13-D13) -> 2 | G13: =IF(F13>=2,"Yes","No") -> Yes | H13: =COUNTIF('Gap Register'!$C$2:$C$40,B13) -> 2 | I13: =_xlfn.MAXIFS('Gap Register'!$N$2:$N$40,'Gap Register'!$C$2:$C$40,B13) -> 20 | J13: =IF(H13=0,"None",IF(I13>=Notes!$B$7,"Critical",IF(I13>=Notes!$B$8,"High",IF(I13>=Notes!$B$9,"Medium","Low")))) -> Critical | K13: =COUNTIF('Improvement Actions'!$C$2:$C$73,B13) -> 6
... A23: Recover | B23: RC.CO | C23: Incident Recovery Communication | D23: 1 | E23: 2 | F23: =MAX(0,E23-D23) -> 1 | G23: =IF(F23>=2,"Yes","No") -> No | H23: =COUNTIF('Gap Register'!$C$2:$C$40,B23) -> 1 | I23: =_xlfn.MAXIFS('Gap Register'!$N$2:$N$40,'Gap Register'!$C$2:$C$40,B23) -> 9 | J23: =IF(H23=0,"None",IF(I23>=Notes!$B$7,"Critical",IF(I23>=Notes!$B$8,"High",IF(I23>=Notes!$B$9,"Medium","Low")))) -> Medium | K23: =COUNTIF('Improvement Actions'!$C$2:$C$73,B23) -> 1
A24: Total | H24: =SUM(H2:H23) -> 39 | K24: =SUM(K2:K23) -> 72

Sheet Notes
A1: CMC Gap Analysis (Simulated)
A2: Purpose | B2: Gap Findings and Improvement Actions for Chaophraya Medical Center (CMC, fictional), grounded in the Interview export. Same content as the six JSON files for Gap-Analysis-Compact.html.
A3: Tiers | B3: Current and Target Tier per Category come from the Interview export and Workshop profile. Edit only if the source changes.
A4: Cells to edit | B4: Blue text is an input: Tiers, Likelihood, Impact, thresholds. Black text is a formula.
A6: Band thresholds (Moderate appetite) | B6: Minimum score
A7: Critical | B7: 20
A8: High | B8: 10
A9: Medium | B9: 5
A10: Low | B10: 1
A12: Scoring | B12: Score = Likelihood (1 to 5) x highest Impact across six areas (1 to 5). The Gap Analysis HTML recalculates after assessor confirmation.
A13: To verify | B13: Current CII and PDPA reporting timelines must be checked against the latest announcements before use in a real procedure.
A14: Not included | B14: Owner, effort, cost, and timing belong to the Roadmap step. Cross-function dependencies are listed in the Depends on column.

Sheet Gap Register
A1: Gap ID | B1: Function | C1: Category | D1: Category name | E1: Basis | F1: Gap title | G1: Gap statement | H1: Consequence | I1: Linked Subcategories | J1: Gap Type | K1: Likelihood (1-5) | L1: Highest Impact (1-5) | M1: Highest impact area | N1: Score | O1: Band
A2: GAP-GV.OC-01 | B2: Govern | C2: GV.OC | D2: Organizational Context | E2: Observed | F2: Legal duties are documented but not maintained or assigned | G2: CMC records some CII and PDPA duties but does not keep the list current or assign owners, so deadlines depend on individuals. | H2: A missed reporting deadline or failed audit brings regulator action against a CII operator and weakens CMC's position after an incident. | I2: GV.OC-03 | J2: Process | K2: 3 | L2: 4 | M2: legal | N2: =K2*L2 -> 12 | O2: =IF(N2>=Notes!$B$7,"Critical",IF(N2>=Notes!$B$8,"High",IF(N2>=Notes!$B$9,"Medium","Low"))) -> High
A3: GAP-GV.OC-02 | B3: Govern | C3: GV.OC | D3: Organizational Context | E3: Observed | F3: Mission, stakeholder needs, and critical dependencies do not guide decisions | G3: Management has not approved which services and dependencies are critical, so recovery and budget priorities rest on opinion. | H3: In an incident, teams argue over what to restore first, and investment goes to systems that matter less than HIS. | I3: GV.OC-01, GV.OC-02, GV.OC-04, GV.OC-05 | J3: Process | K3: 3 | L3: 4 | M3: ops | N3: =K3*L3 -> 12 | O3: =IF(N3>=Notes!$B$7,"Critical",IF(N3>=Notes!$B$8,"High",IF(N3>=Notes!$B$9,"Medium","Low"))) -> High
A4: GAP-GV.RM-01 | B4: Govern | C4: GV.RM | D4: Risk Management Strategy | E4: Observed | F4: No approved risk objectives, risk method, or appetite | G4: Risk decisions follow individual judgment rather than a method management approved, so executives cannot see which risks exceed tolerance. | H4: The CEO funds or declines security work without a view of risk, so large exposures stay open while small ones consume budget. | I4: GV.RM-01, GV.RM-02, GV.RM-06 | J4: Governance | K4: 4 | L4: 4 | M4: fin | N4: =K4*L4 -> 16 | O4: =IF(N4>=Notes!$B$7,"Critical",IF(N4>=Notes!$B$8,"High",IF(N4>=Notes!$B$9,"Medium","Low"))) -> High
A5: GAP-GV.RM-02 | B5: Govern | C5: GV.RM | D5: Risk Management Strategy | E5: Inferred (Medium) | F5: Cyber risk is missing from enterprise risk reporting and strategy | G5: Cybersecurity risk is probably outside enterprise risk reporting, so the board sees it as an IT cost rather than a business risk. | H5: Security budget requests compete without risk evidence, and the board learns of exposure only after an incident. | I5: GV.RM-03, GV.RM-04, GV.RM-05, GV.RM-07 | J5: Governance | K5: 3 | L5: 3 | M5: fin | N5: =K5*L5 -> 9 | O5: =IF(N5>=Notes!$B$7,"Critical",IF(N5>=Notes!$B$8,"High",IF(N5>=Notes!$B$9,"Medium","Low"))) -> Medium
A6: GAP-GV.RR-01 | B6: Govern | C6: GV.RR | D6: Roles, Responsibilities, and Authorities | E6: Observed | F6: No accountable executive or resourced security function | G6: Security duties sit with IT staff beside operations, and the new Security Manager has no written mandate, authority, or budget. | H6: Risky changes proceed without a security decision, and no one can order containment or fund remediation during an incident. | I6: GV.RR-01, GV.RR-03 | J6: Governance | K6: 4 | L6: 4 | M6: ops | N6: =K6*L6 -> 16 | O6: =IF(N6>=Notes!$B$7,"Critical",IF(N6>=Notes!$B$8,"High",IF(N6>=Notes!$B$9,"Medium","Low"))) -> High
A7: GAP-GV.RR-02 | B7: Govern | C7: GV.RR | D7: Roles, Responsibilities, and Authorities | E7: Observed | F7: System ownership and HR practices omit security duties | G7: PACS and Active Directory have no named business owner, and HR practices carry no security duties, so risk on them has no accountable person. | H7: Control changes on PACS and Active Directory stall, and risk acceptances are made without the people who bear the effect. | I7: GV.RR-02, GV.RR-04 | J7: Governance | K7: 3 | L7: 4 | M7: ops | N7: =K7*L7 -> 12 | O7: =IF(N7>=Notes!$B$7,"Critical",IF(N7>=Notes!$B$8,"High",IF(N7>=Notes!$B$9,"Medium","Low"))) -> High
A8: GAP-GV.PO-01 | B8: Govern | C8: GV.PO | D8: Policy | E8: Observed | F8: No approved security policy covers current systems and duties | G8: CMC has only an unsigned 2019 draft policy that staff never received, so no binding rule covers PDPA, CII, or current systems. | H8: Staff and vendors cannot be held to any rule, and an auditor or regulator finds no approved basis for CMC's controls. | I8: GV.PO-01 | J8: Governance | K8: 4 | L8: 3 | M8: ops | N8: =K8*L8 -> 12 | O8: =IF(N8>=Notes!$B$7,"Critical",IF(N8>=Notes!$B$8,"High",IF(N8>=Notes!$B$9,"Medium","Low"))) -> High
A9: GAP-GV.PO-02 | B9: Govern | C9: GV.PO | D9: Policy | E9: Observed | F9: Policy exceptions are accepted without a record or expiry | G9: CMC has no exception process, so control bypasses such as shared administrator accounts continue without an owner, expiry, or visible risk. | H9: Accepted risks pile up unseen, and shared accounts prevent tracing who acted on patient systems after a breach. | I9: GV.PO-02 | J9: Process | K9: 4 | L9: 4 | M9: ops | N9: =K9*L9 -> 16 | O9: =IF(N9>=Notes!$B$7,"Critical",IF(N9>=Notes!$B$8,"High",IF(N9>=Notes!$B$9,"Medium","Low"))) -> High
A10: GAP-GV.OV-01 | B10: Govern | C10: GV.OV | D10: Oversight | E10: Observed | F10: Leadership receives no regular cybersecurity reporting | G10: Executives hear about cybersecurity only after events, so they cannot judge progress or decide on resources. | H10: The CEO cannot tell whether risk is falling, so funding decisions follow the latest incident and not program results. | I10: GV.OV-01, GV.OV-02, GV.OV-03 | J10: Governance | K10: 3 | L10: 3 | M10: fin | N10: =K10*L10 -> 9 | O10: =IF(N10>=Notes!$B$7,"Critical",IF(N10>=Notes!$B$8,"High",IF(N10>=Notes!$B$9,"Medium","Low"))) -> Medium
A11: GAP-GV.SC-01 | B11: Govern | C11: GV.SC | D11: Cybersecurity Supply Chain Risk Management | E11: Observed | F11: Critical vendor contracts carry no security duties or processing agreements | G11: Contracts with critical vendors lack security duties and processing agreements, so CMC cannot require protection of patient data. | H11: A breach at the HIS or PACS vendor reaches patient data with no contract duty to notify CMC or cooperate. | I11: GV.SC-01, GV.SC-03, GV.SC-05, GV.SC-06 | J11: Process | K11: 4 | L11: 5 | M11: data | N11: =K11*L11 -> 20 | O11: =IF(N11>=Notes!$B$7,"Critical",IF(N11>=Notes!$B$8,"High",IF(N11>=Notes!$B$9,"Medium","Low"))) -> Critical
A12: GAP-GV.SC-02 | B12: Govern | C12: GV.SC | D12: Cybersecurity Supply Chain Risk Management | E12: Observed | F12: Vendors reach critical systems through uncontrolled remote tools | G12: Vendors connect through always-on remote tools that CMC does not control, and they take no part in incident planning or exit steps. | H12: An attacker who takes over a vendor session reaches HIS or PACS directly, as in the attack path used against the peer hospital. | I12: GV.SC-02, GV.SC-04, GV.SC-08, GV.SC-09, GV.SC-10 | J12: Process | K12: 4 | L12: 5 | M12: ops | N12: =K12*L12 -> 20 | O12: =IF(N12>=Notes!$B$7,"Critical",IF(N12>=Notes!$B$8,"High",IF(N12>=Notes!$B$9,"Medium","Low"))) -> Critical
A13: GAP-ID.AM-01 | B13: Identify | C13: ID.AM | D13: Asset Management | E13: Observed | F13: Software, cloud, and data-flow inventories are missing | G13: CMC lists hardware and medical devices but not software, cloud services, or data flows, so exposure and breach scope cannot be mapped. | H13: Unlisted software stays unpatched, and after a breach CMC cannot say which patient records left the hospital. | I13: ID.AM-02, ID.AM-03, ID.AM-04, ID.AM-07 | J13: Process | K13: 3 | L13: 4 | M13: legal | N13: =K13*L13 -> 12 | O13: =IF(N13>=Notes!$B$7,"Critical",IF(N13>=Notes!$B$8,"High",IF(N13>=Notes!$B$9,"Medium","Low"))) -> High
... A40: GAP-RC.CO-01 | B40: Recover | C40: RC.CO | D40: Incident Recovery Communication | E40: Observed | F40: No process to communicate during recovery | G40: No process or spokesperson informs patients, referring hospitals, and regulators as services return. | H40: Recovery updates are informal and inconsistent, which prolongs loss of trust. | I40: RC.CO-03, RC.CO-04 | J40: Process | K40: 3 | L40: 3 | M40: rep | N40: =K40*L40 -> 9 | O40: =IF(N40>=Notes!$B$7,"Critical",IF(N40>=Notes!$B$8,"High",IF(N40>=Notes!$B$9,"Medium","Low"))) -> Medium

Sheet Improvement Actions
A1: IMP ID | B1: Gap ID | C1: Category | D1: Angle | E1: Action | F1: Gap Type | G1: Systems | H1: Depends on (same Function) | I1: Gap band
A2: IMP-GV.OC-01-01 | B2: GAP-GV.OC-01 | C2: GV.OC | D2: Fix | E2: Add an owner, review date, and deadline to each duty in the register of CII and PDPA requirements | F2: Process | I2: =INDEX('Gap Register'!$O$2:$O$40,MATCH(B2,'Gap Register'!$A$2:$A$40,0)) -> High
A3: IMP-GV.OC-01-02 | B3: GAP-GV.OC-01 | C3: GV.OC | D3: Prevent | E3: Review the register every year and after each law or regulator change | F3: Process | I3: =INDEX('Gap Register'!$O$2:$O$40,MATCH(B3,'Gap Register'!$A$2:$A$40,0)) -> High
A4: IMP-GV.OC-02-01 | B4: GAP-GV.OC-02 | C4: GV.OC | D4: Fix | E4: Present the Criticality A list to the CIO and CEO for approval and link it to recovery priorities | F4: Process | I4: =INDEX('Gap Register'!$O$2:$O$40,MATCH(B4,'Gap Register'!$A$2:$A$40,0)) -> High
A5: IMP-GV.RM-01-01 | B5: GAP-GV.RM-01 | C5: GV.RM | D5: Fix | E5: Approve a risk appetite statement and one risk method | F5: Governance | I5: =INDEX('Gap Register'!$O$2:$O$40,MATCH(B5,'Gap Register'!$A$2:$A$40,0)) -> High
A6: IMP-GV.RM-01-02 | B6: GAP-GV.RM-01 | C6: GV.RM | D6: Fix | E6: Start a shared risk register that executives review | F6: Governance | H6: IMP-GV.RM-01-01 | I6: =INDEX('Gap Register'!$O$2:$O$40,MATCH(B6,'Gap Register'!$A$2:$A$40,0)) -> High
A7: IMP-GV.RM-02-01 | B7: GAP-GV.RM-02 | C7: GV.RM | D7: Prevent | E7: Add cybersecurity risks to the enterprise risk report presented to the board each quarter | F7: Governance | H7: IMP-GV.RM-01-01 | I7: =INDEX('Gap Register'!$O$2:$O$40,MATCH(B7,'Gap Register'!$A$2:$A$40,0)) -> Medium
A8: IMP-GV.RR-01-01 | B8: GAP-GV.RR-01 | C8: GV.RR | D8: Fix | E8: Issue a mandate letter for the Security Manager covering authority, reporting line, and budget, and name an accountable executive | F8: Governance | I8: =INDEX('Gap Register'!$O$2:$O$40,MATCH(B8,'Gap Register'!$A$2:$A$40,0)) -> High
A9: IMP-GV.RR-02-01 | B9: GAP-GV.RR-02 | C9: GV.RR | D9: Fix | E9: Name a business owner for PACS and Active Directory and record the owner duties | F9: Governance | G9: PACS, Active Directory | I9: =INDEX('Gap Register'!$O$2:$O$40,MATCH(B9,'Gap Register'!$A$2:$A$40,0)) -> High
A10: IMP-GV.RR-02-02 | B10: GAP-GV.RR-02 | C10: GV.RR | D10: Prevent | E10: Add security duties to job descriptions and joiner, mover, and leaver steps with HR | F10: Governance | I10: =INDEX('Gap Register'!$O$2:$O$40,MATCH(B10,'Gap Register'!$A$2:$A$40,0)) -> High
A11: IMP-GV.PO-01-01 | B11: GAP-GV.PO-01 | C11: GV.PO | D11: Fix | E11: Approve the Information Security Policy and communicate it to all staff and vendors | F11: Governance | I11: =INDEX('Gap Register'!$O$2:$O$40,MATCH(B11,'Gap Register'!$A$2:$A$40,0)) -> High
A12: IMP-GV.PO-02-01 | B12: GAP-GV.PO-02 | C12: GV.PO | D12: Handle exceptions | E12: Introduce a policy exception form with risk owner, compensating control, and expiry date | F12: Process | H12: IMP-GV.PO-01-01 | I12: =INDEX('Gap Register'!$O$2:$O$40,MATCH(B12,'Gap Register'!$A$2:$A$40,0)) -> High
A13: IMP-GV.OV-01-01 | B13: GAP-GV.OV-01 | C13: GV.OV | D13: Fix | E13: Set up a security steering committee that meets quarterly with a baseline metric set | F13: Governance | I13: =INDEX('Gap Register'!$O$2:$O$40,MATCH(B13,'Gap Register'!$A$2:$A$40,0)) -> Medium
A14: IMP-GV.SC-01-01 | B14: GAP-GV.SC-01 | C14: GV.SC | D14: Fix | E14: Add security clauses and a data processing agreement to the HIS and PACS vendor contracts | F14: Process | G14: HIS, PACS | I14: =INDEX('Gap Register'!$O$2:$O$40,MATCH(B14,'Gap Register'!$A$2:$A$40,0)) -> Critical
A15: IMP-GV.SC-01-02 | B15: GAP-GV.SC-01 | C15: GV.SC | D15: Prevent | E15: Require security due diligence before every new critical vendor contract | F15: Process | I15: =INDEX('Gap Register'!$O$2:$O$40,MATCH(B15,'Gap Register'!$A$2:$A$40,0)) -> Critical
A16: IMP-GV.SC-02-01 | B16: GAP-GV.SC-02 | C16: GV.SC | D16: Fix | E16: Replace unattended vendor remote tools with a supervised access method protected by MFA | F16: Process | G16: HIS, PACS | I16: =INDEX('Gap Register'!$O$2:$O$40,MATCH(B16,'Gap Register'!$A$2:$A$40,0)) -> Critical
A17: IMP-GV.SC-02-02 | B17: GAP-GV.SC-02 | C17: GV.SC | D17: Find | E17: Rank all vendors by criticality and list the access each one holds | F17: Process | I17: =INDEX('Gap Register'!$O$2:$O$40,MATCH(B17,'Gap Register'!$A$2:$A$40,0)) -> Critical
A18: IMP-GV.SC-02-03 | B18: GAP-GV.SC-02 | C18: GV.SC | D18: Prevent | E18: Include critical vendors in incident response planning and contract exit steps | F18: Process | I18: =INDEX('Gap Register'!$O$2:$O$40,MATCH(B18,'Gap Register'!$A$2:$A$40,0)) -> Critical
A19: IMP-ID.AM-01-01 | B19: GAP-ID.AM-01 | C19: ID.AM | D19: Find | E19: Build a software and cloud service inventory with version and support status, Criticality A systems first | F19: Process | I19: =INDEX('Gap Register'!$O$2:$O$40,MATCH(B19,'Gap Register'!$A$2:$A$40,0)) -> High
A20: IMP-ID.AM-01-02 | B20: GAP-ID.AM-01 | C20: ID.AM | D20: Find | E20: Map network and patient data flows for HIS, PACS, LIS, and ERP and start the Record of Processing Activities (ROPA) | F20: Process | I20: =INDEX('Gap Register'!$O$2:$O$40,MATCH(B20,'Gap Register'!$A$2:$A$40,0)) -> High
A21: IMP-ID.AM-02-01 | B21: GAP-ID.AM-02 | C21: ID.AM | D21: Fix | E21: Assign an owner and criticality to every hardware and medical device record | F21: Process | I21: =INDEX('Gap Register'!$O$2:$O$40,MATCH(B21,'Gap Register'!$A$2:$A$40,0)) -> Medium
A22: IMP-ID.AM-02-02 | B22: GAP-ID.AM-02 | C22: ID.AM | D22: Prevent | E22: Require inventory update in change approval and reconcile it every six months | F22: Process | H22: IMP-ID.AM-02-01 | I22: =INDEX('Gap Register'!$O$2:$O$40,MATCH(B22,'Gap Register'!$A$2:$A$40,0)) -> Medium
A23: IMP-ID.RA-01-01 | B23: GAP-ID.RA-01 | C23: ID.RA | D23: Fix | E23: Run authenticated vulnerability scans monthly on Criticality A systems and the hospital website and track findings to closure | F23: Technology | G23: HIS, PACS, Hospital website | I23: =INDEX('Gap Register'!$O$2:$O$40,MATCH(B23,'Gap Register'!$A$2:$A$40,0)) -> Critical
A24: IMP-ID.RA-01-02 | B24: GAP-ID.RA-01 | C24: ID.RA | D24: Prevent | E24: Set remediation timelines by severity and report them to the steering committee | F24: Technology | H24: IMP-ID.RA-01-01 | I24: =INDEX('Gap Register'!$O$2:$O$40,MATCH(B24,'Gap Register'!$A$2:$A$40,0)) -> Critical
A25: IMP-ID.RA-02-01 | B25: GAP-ID.RA-02 | C25: ID.RA | D25: Find | E25: Write ransomware and third-party access threat scenarios from the peer hospital incident | F25: Process | I25: =INDEX('Gap Register'!$O$2:$O$40,MATCH(B25,'Gap Register'!$A$2:$A$40,0)) -> High
A26: IMP-ID.RA-02-02 | B26: GAP-ID.RA-02 | C26: ID.RA | D26: Prevent | E26: Subscribe to a sector threat advisory source and review it monthly | F26: Process | I26: =INDEX('Gap Register'!$O$2:$O$40,MATCH(B26,'Gap Register'!$A$2:$A$40,0)) -> High
A27: IMP-ID.IM-01-01 | B27: GAP-ID.IM-01 | C27: ID.IM | D27: Find | E27: Run a first tabletop exercise on ransomware and record the improvements | F27: Evidence | I27: =INDEX('Gap Register'!$O$2:$O$40,MATCH(B27,'Gap Register'!$A$2:$A$40,0)) -> High
A28: IMP-ID.IM-01-02 | B28: GAP-ID.IM-01 | C28: ID.IM | D28: Prevent | E28: Open an improvement register fed by exercises, audits, and incidents | F28: Evidence | I28: =INDEX('Gap Register'!$O$2:$O$40,MATCH(B28,'Gap Register'!$A$2:$A$40,0)) -> High
A29: IMP-PR.AA-01-01 | B29: GAP-PR.AA-01 | C29: PR.AA | D29: Fix | E29: Enforce MFA for administrators on HIS, PACS, and Active Directory | F29: Technology | G29: HIS, PACS, Active Directory | I29: =INDEX('Gap Register'!$O$2:$O$40,MATCH(B29,'Gap Register'!$A$2:$A$40,0)) -> Critical
A30: IMP-PR.AA-01-02 | B30: GAP-PR.AA-01 | C30: PR.AA | D30: Fix | E30: Require MFA and session logging for vendor remote access and remove unattended remote tools | F30: Technology | G30: HIS, PACS | I30: =INDEX('Gap Register'!$O$2:$O$40,MATCH(B30,'Gap Register'!$A$2:$A$40,0)) -> Critical
A31: IMP-PR.AA-01-03 | B31: GAP-PR.AA-01 | C31: PR.AA | D31: Find | E31: List every system with its authentication method and MFA status, Criticality A and B first | F31: Technology | I31: =INDEX('Gap Register'!$O$2:$O$40,MATCH(B31,'Gap Register'!$A$2:$A$40,0)) -> Critical
A32: IMP-PR.AA-01-04 | B32: GAP-PR.AA-01 | C32: PR.AA | D32: Prevent | E32: Approve an authentication standard that requires MFA for new systems | F32: Technology | I32: =INDEX('Gap Register'!$O$2:$O$40,MATCH(B32,'Gap Register'!$A$2:$A$40,0)) -> Critical
A33: IMP-PR.AA-01-05 | B33: GAP-PR.AA-01 | C33: PR.AA | D33: Handle exceptions | E33: Place systems that cannot support MFA behind a jump host with session logging and a time-limited risk acceptance | F33: Technology | H33: IMP-PR.AA-01-04 | I33: =INDEX('Gap Register'!$O$2:$O$40,MATCH(B33,'Gap Register'!$A$2:$A$40,0)) -> Critical
A34: IMP-PR.AA-02-01 | B34: GAP-PR.AA-02 | C34: PR.AA | D34: Fix | E34: Run a first access review on Criticality A systems, privileged accounts first | F34: Process | G34: HIS, PACS, Active Directory | I34: =INDEX('Gap Register'!$O$2:$O$40,MATCH(B34,'Gap Register'!$A$2:$A$40,0)) -> High
A35: IMP-PR.AA-02-02 | B35: GAP-PR.AA-02 | C35: PR.AA | D35: Find | E35: Identify shared and generic administrator accounts on PACS, Active Directory, and the website | F35: Process | G35: PACS, Active Directory | I35: =INDEX('Gap Register'!$O$2:$O$40,MATCH(B35,'Gap Register'!$A$2:$A$40,0)) -> High
A36: IMP-PR.AA-02-03 | B36: GAP-PR.AA-02 | C36: PR.AA | D36: Prevent | E36: Link joiner, mover, and leaver steps to HR and set a six-month review cycle | F36: Process | I36: =INDEX('Gap Register'!$O$2:$O$40,MATCH(B36,'Gap Register'!$A$2:$A$40,0)) -> High
A37: IMP-PR.AA-02-04 | B37: GAP-PR.AA-02 | C37: PR.AA | D37: Fix | E37: Keep server room access logs and review the access list each quarter | F37: Process | I37: =INDEX('Gap Register'!$O$2:$O$40,MATCH(B37,'Gap Register'!$A$2:$A$40,0)) -> High
A38: IMP-PR.AT-01-01 | B38: GAP-PR.AT-01 | C38: PR.AT | D38: Fix | E38: Record completion of an annual awareness program for all staff | F38: Evidence | I38: =INDEX('Gap Register'!$O$2:$O$40,MATCH(B38,'Gap Register'!$A$2:$A$40,0)) -> Medium
A39: IMP-PR.DS-01-01 | B39: GAP-PR.DS-01 | C39: PR.DS | D39: Fix | E39: Add an offline or immutable backup copy for HIS, ERP, Active Directory, and Microsoft 365 data | F39: Technology | G39: HIS, ERP, Active Directory | I39: =INDEX('Gap Register'!$O$2:$O$40,MATCH(B39,'Gap Register'!$A$2:$A$40,0)) -> Critical
A40: IMP-PR.DS-01-02 | B40: GAP-PR.DS-01 | C40: PR.DS | D40: Fix | E40: Run and record a restore test on HIS, Microsoft 365, and Active Directory with recovery time measured | F40: Technology | G40: HIS, Active Directory | I40: =INDEX('Gap Register'!$O$2:$O$40,MATCH(B40,'Gap Register'!$A$2:$A$40,0)) -> Critical
...
